Workbook

Sheet Annotations
A1: File | B1: Assigned_to | C1: Status | D1: Correct answer | E1: Explanation 1 | F1: Explanation 2 | G1: Explanation 3 | H1: Literal_Description | I1: Humor Style | J1: Humor style secondary | K1: Contextual Knowledge | L1: Contextual Knowledge secondary | M1: Duplicate check
A2: 13ibrc1 | B2: Sabrina | C2: Done | D2: Let’s start with the comic. The two shallow and wide glasses hold the same amount of liquid. The next panels you see the transfer of the liquid to the taller thin glass. The volume and quantity of the liquid remains the same. The third panel the child points to the taller glass. This whole set up is a standard test for the developmental level of a child. The goal is to tell which glass holds the most liquid. It’s commonly for young children to look at the glass and see that it’s taller and say that has the most liquid, simply because they lack the understanding to consider the width of the glass. This occurs even if you pour it right in front of them. So the comment from Lara Trump follows a similar logic. The red portion of the map outlines Republican districts, the blue outlines Democratic districts. She is implying that because the red covers the majority of the map, most of the country is Republican and therefor would be unable to impeach them. The comic is pointing out that although the red map covers more land than blue, it does not accurately convey the number of voters, because the blue districts hold the same or more of the population due to population density. | E2: A Reddit screenshot shows a tweet with a red-and-blue map of the United States and the text “Try to impeach this.” Under it, another user replies with a three-panel image of a child pouring liquid between containers. | F2: Trump’s daughter appears to be trolling people online by posting a map that makes it look like far more people voted for her dad. It comes across as a deliberately provocative post meant to annoy or bait people on X. | G2: She seems to have edited or presented the voting map in a way that makes it look much redder than it actually is. The image gives the impression that the results are being manipulated visually to support her point. | H2: A Reddit screenshot shows a tweet with a red-and-blue map of the United States and the text “Try to impeach this.” Under it, another user replies with a three-panel image of a child pouring liquid between containers. | I2: Comparison | J2: Sarcasm/Irony | K2: Logical | L2: politics | M2: =IF(COUNTIF($A$2:A2, A2)>1, "Dublet", "OK") -> OK
A3: 14ys2z4 | B3: Naomi | C3: Done | D3: Centrists or people that dont participate in politics are often viewed as grillers, they just want to take a load off and not worry about the chaos. Daughter is saying the boyfriend doesnt have to worry about her dad taking a stand to them because he doesnt stand for anything basically | E3: A four-panel illustrated comic. The first panel shows a teenage couple about to kiss on a bed; the boy nervously asks, "W-wait... isn't your dad home?" The second panel shows the girl reassuring him, "It's okay. He won't do anything. Never does." The third panel shows a bald, hollow-eyed dad at a flaming grill with the caption "My dad's a griller." The fourth panel is a close-up of the same gaunt, exhausted-looking father holding a beer can under a starry night sky. | F3: The "griller" subspecies in the wild — beer in hand, soul somewhere else. | G3: Dad has transcended fatherhood and entered his charcoal-priest era. | H3: A four-panel illustrated comic. The first panel shows a teenage couple about to kiss on a bed; the boy nervously asks, "W-wait... isn't your dad home?" The second panel shows the girl reassuring him, "It's okay. He won't do anything. Never does." The third panel shows a bald, hollow-eyed dad at a flaming grill with the caption "My dad's a griller." The fourth panel is a close-up of the same gaunt, exhausted-looking father holding a beer can under a starry night sky. | I3: Wordplay | J3: Situational | K3: politics | L3: Logical | M3: =IF(COUNTIF($A$2:A3, A3)>1, "Dublet", "OK") -> OK
A4: 1587f2g | B4: Naomi | C4: Done | D4: I saw an explanation for this a while ago, you have to know hair to get this one. The haircut on the right is mid-hairdress, and the one on the left is the finished look. So while the one on the right looks more artificial and the one on the left looks more natural, the one on the left is actually the complete look. It's essentially saying that you put more effort into yourself than the chick your bf is banging, and he doesn't appreciate that. | E4: Its hilarious because the two are exactly identical. | F4: The image shows a side-by-side comparison of two blonde hairstyles: soft, brushed-out waves on the left and tight, unbrushed ringlets on the right. The text at the top reads "you vs. the girl he cheats with," while a social media comment at the bottom states that the user enjoys the idea of men not understanding the post. | G4: Its because the two images show the hair curling in opposite dorections in the image making the joke that men are never satisifed and are destined to cheat. | H4: The image shows a side-by-side comparison of two blonde hairstyles: soft, brushed-out waves on the left and tight, unbrushed ringlets on the right. The text at the top reads "you vs. the girl he cheats with," while a social media comment at the bottom states that the user enjoys the idea of men not understanding the post. | I4: Exaggeration | J4: Comparison | K4: Technical | L4: Social conventions | M4: =IF(COUNTIF($A$2:A4, A4)>1, "Dublet", "OK") -> OK
A5: 15a2flm | B5: Naomi | C5: Done | D5: With a new job, you can get days off by saying your grandparent died. You're new at the company so no one knows that they're already dead. Use up to 4 times. | E5: Day one of a new job and grandma is suddenly alive, dying, and Catholic again. | F5: A screenshot of a tweet from "stoned cold fox" (@roastmalone_) reading: "the best part of starting a new job is all 4 of your grandparents are alive again." | G5: PTO loophole that resurrects your entire family tree on demand. | H5: A screenshot of a tweet from "stoned cold fox" (@roastmalone_) reading: "the best part of starting a new job is all 4 of your grandparents are alive again." | I5: Dark Humor | J5: Situational | K5: General knowledge | L5: Social conventions | M5: =IF(COUNTIF($A$2:A5, A5)>1, "Dublet", "OK") -> OK
A6: 15gdv3c | B6: Naomi | C6: Done | D6: Morning after pill | E6: A meme captioned "When you're on deployment and your wife spends $50 at CVS at 8:21am" with a close-up photo of a soldier in a helmet with a single tear running down his cheek. | F6: The exact timestamp where a deployment check-in becomes a Maury episode. | G6: Pre-9 AM pharmacy receipt that delivers a paternity verdict before breakfast. | H6: A meme captioned "When you're on deployment and your wife spends $50 at CVS at 8:21am" with a close-up photo of a soldier in a helmet with a single tear running down his cheek. | I6: Dark Humor | J6: Sarcasm/Irony | K6: General knowledge | L6: Logical | M6: =IF(COUNTIF($A$2:A6, A6)>1, "Dublet", "OK") -> OK
A7: 15h4szq | B7: Naomi | C7: Done | D7: In Platos republic, Plato argues that the best society is one in which a astiorcratic elite who have spent their whole lives training and learning the art of statecraft should be the rulers. The idea is that if someone has been trained in the art of statecraft and philosophy from birth they will be the idea ruler or "philosopher king" who seeks council from other who are skilled in their professions. Super simplified, in an ideal world, people would fulfil a specific role and be happy about it. In Barbie, each of the Barbies holds a specific role they were created for, their ruler rules and does so well, because they were created to rule. The Barbies are happy about it. You could argue it looks like Platos ideal republic | E7: This is because Plato is one of the first people to come up with an idea of society and barbie is a modern version of it. | F7: A two-panel meme that humorously labels the 2023 Barbie movie poster as "the anime" and the cover of Plato's The Republic as "the manga," satirizing the common gatekeeping trope that one cannot appreciate an adaptation without reading its "source material." | G7: It is incongruous which makes it funny since Plato is an important philosopher and he ahs nothing in common with childrens toy brand. | H7: A two-panel meme that humorously labels the 2023 Barbie movie poster as "the anime" and the cover of Plato's The Republic as "the manga," satirizing the common gatekeeping trope that one cannot appreciate an adaptation without reading its "source material." | I7: Comparison | J7: Situational | K7: History/Mythology | L7: Pop culture | M7: =IF(COUNTIF($A$2:A7, A7)>1, "Dublet", "OK") -> OK
A8: 15oof8t | B8: Naomi | C8: Done | D8: The joke is that young girls keep asking their bfs stupid shit like would you still love me if I were a worm?" A bunch of weird things can be slotted in there, but worm seems to be the most popular one. The bouncer is crying because of the intense love he knows the man must feel for his "girlfriend" since they're still together despite her being now a worm." | E8: Door policy bent for the most heartfelt parasitic relationship at the club. | F8: A three-panel comic by @beetlemoses. The first panel shows a bald, bearded bouncer stopping a man saying "Whoa, pal. No entry without a girl." The second panel reveals the man's huge muscular chest with a tapeworm peeking out as he says "But sir—I'm with my girlfriend." The third panel shows the bouncer tearfully waving the velvet rope aside while the man walks past, giving a thumbs-up. | G8: A bouncer reduced to tears by an unconventional plus-one situation. | H8: A three-panel comic by @beetlemoses. The first panel shows a bald, bearded bouncer stopping a man saying "Whoa, pal. No entry without a girl." The second panel reveals the man's huge muscular chest with a tapeworm peeking out as he says "But sir—I'm with my girlfriend." The third panel shows the bouncer tearfully waving the velvet rope aside while the man walks past, giving a thumbs-up. | I8: Incongruity | J8: Surprise | K8: meme | L8: Pop culture | M8: =IF(COUNTIF($A$2:A8, A8)>1, "Dublet", "OK") -> OK
A9: 15upbjf | B9: Naomi | C9: Done | D9: Those are RCA cables. The yellow one is for video, white and red are audio. Van Gogh cut off a piece of his left ear, so he’s missing one of the audio cables. Beethoven was deaf, so he’s missing both audio cables. Stevie Wonder is blind, so he’s missing the video. | E9: The pre-HDMI cable hierarchy, narrated entirely through famous artists. | F9: Three historical figures matched with the AV cables that bypass their respective disabilities. | G9: A meme captioned "HDMI kids won't understand" showing three rows: Vincent van Gogh's self-portrait paired with yellow and red RCA cables, a portrait of Beethoven paired with a single yellow RCA cable, and a photo of Stevie Wonder paired with red and white RCA cables. | H9: A meme captioned "HDMI kids won't understand" showing three rows: Vincent van Gogh's self-portrait paired with yellow and red RCA cables, a portrait of Beethoven paired with a single yellow RCA cable, and a photo of Stevie Wonder paired with red and white RCA cables. | I9: Wordplay | J9: Comparison | K9: Technical | L9: History/Mythology | M9: =IF(COUNTIF($A$2:A9, A9)>1, "Dublet", "OK") -> OK
A10: 15vbd1p | B10: Sabrina | C10: Done | D10: At first I thought this was her being pregnant but I'm pretty sure it's actually another dude hiding in the closet cuz she's cheating. The heartbeats would be closer if she was pregnant. | E10: He starts crying because the heartbeat sensor he made actually works. In that moment, he is probably imagining all the people it could help, and it hits him that his invention might genuinely matter. | F10: He is crying because there is a bomb next to his girlfriend, and he has no idea how to tell her. She looks so calm and happy, which makes the situation feel even worse. | G10: A comic shows a woman lying on a bed while someone uses a heartbeat sensor nearby. In the next panel, a young man holding the device is crying with an emotional expression. | H10: A comic shows a woman lying on a bed while someone uses a heartbeat sensor nearby. In the next panel, a young man holding the device is crying with an emotional expression. | I10: Dark Humor | J10: Incongruity | K10: Logical | L10: Social conventions | M10: =IF(COUNTIF($A$2:A10, A10)>1, "Dublet", "OK") -> OK
A11: 15yqaf6 | B11: Naomi | C11: Done | D11: the double slit experiment, particles behave differently when they are observed. | E11: It humorously depicts paranoia and how you can feel things when your not looking. | F11: This meme depicts object permemanence. | G11: A two-panel meme featuring the "Monkey Puppet" character looking away and then forward, paired with diagrams | H11: A two-panel meme featuring the "Monkey Puppet" character looking away and then forward, paired with diagrams | I11: Incongruity | J11: Comparison | K11: Technical | L11: General knowledge | M11: =IF(COUNTIF($A$2:A11, A11)>1, "Dublet", "OK") -> OK
A12: 15aafk0 | B12: Naomi | C12: Done | D12: Everyone whose ages 12+ and older knows that the Harry Potter series deals with magic and eugenics. When the series first came out, it was vilified by fundamentalist Christians, mostly right wingers, for glorifying and promoting witchcraft. Naturally, the kids and the alternative crowd who had left wing views thought the world of Harry Potter was a safe space for their fascination with wand waving and British people, both of which are pretty gay. However, that all changed when J.K Rowling, the creator of the series made a controversial tweet ( Or Xeet \*Point and wink\*) about her feelings on trans people. The fandom quickly fell apart after this, resulting in most of the fandom in canceling Rowling by giving her the avada kedavra treatment. Ironically, the same right wingers who once called for her books to be banned and burned are now Rowling's biggest supports. Kind of like when the racists left the Democratic party after LBJ thought black people were cool. The joke here is that Harry Potter went from being loved by witchy girls to far right extremists after one tweet (Or Xeet \*Point and Wink\*). Now if you'll excuse me, I've just been sorted into Slytherin house and feel the urge to make fun of some mudbloods. ROADHOUSE! | E12: The Harry Potter box set quietly switching political affiliations in the night. | F12: A Facebook post from "The Brian Nichols Show" reading "Left wing literature, 2013 / Right wing literature, 2023" with two side-by-side images of the same Harry Potter complete book box set, the post having 42K reactions, 4.1K comments, and 5.3K shares. | G12: Same boxed set, two decades, opposite team jerseys. | H12: A Facebook post from "The Brian Nichols Show" reading "Left wing literature, 2013 / Right wing literature, 2023" with two side-by-side images of the same Harry Potter complete book box set, the post having 42K reactions, 4.1K comments, and 5.3K shares. | I12: Sarcasm/Irony | J12: Comparison | K12: Pop culture | L12: politics | M12: =IF(COUNTIF($A$2:A12, A12)>1, "Dublet", "OK") -> OK
A13: 164v3oo | B13: Naomi | C13: Done | D13: If you squint it looks like the painting girl with a pearl earring" The shirt of the girl on the left is the face." | E13: A meme captioned "Hold your phone as far from you as you can and squint your eyes" with two flushed-face emojis, above a black-and-white photo of two young girls in matching sweaters sitting together in a grassy field, smiling at each other. | F13: Optical illusion gag delivered via blurred sweater geometry. | G13: When pareidolia and a low-resolution sweater conspire to trick the viewer. | H13: A meme captioned "Hold your phone as far from you as you can and squint your eyes" with two flushed-face emojis, above a black-and-white photo of two young girls in matching sweaters sitting together in a grassy field, smiling at each other. | I13: Surprise | J13: Situational | K13: Logical | L13: General knowledge | M13: =IF(COUNTIF($A$2:A13, A13)>1, "Dublet", "OK") -> OK
... A39: 198awkk | B39: Naomi | C39: Done | D39: This is a popular riddle set up where one person tells the truth and the other always lies. You ask them one question to see which one is which. In this case, the setup asks the question, “do you understand the rules?” The guards both say “yes.” Since one always lies and one always tells the truth, it means that one of the guards is lying and doesn’t understand the rules | E39: Three "yes" answers and zero ways to tell which guard is lying. | F39: A three-panel comic by The Jenkins Comic. The first panel shows a top-hatted character explaining to a person in a red shirt: "...so one guard always tells the truth, and one always lies. But you don't know who's who." The second panel shows him concluding "And that's pretty much all the rules of the puzzle. Understand?" The third panel shows the person in red and both armored guards all saying "Yes" in unison. | G39: The classic logic puzzle, ruined by group consensus. | H39: A three-panel comic by The Jenkins Comic. The first panel shows a top-hatted character explaining to a person in a red shirt: "...so one guard always tells the truth, and one always lies. But you don't know who's who." The second panel shows him concluding "And that's pretty much all the rules of the puzzle. Understand?" The third panel shows the person in red and both armored guards all saying "Yes" in unison. | I39: Wordplay | J39: Sarcasm/Irony | K39: General knowledge | L39: Logical | M39: =IF(COUNTIF($A$2:A39, A39)>1, "Dublet", "OK") -> OK
A40: 19994ey | B40: Sabrina | C40: Done | D40: I'm assuming the idea that someone would think it's a gunshot in that neighborhood is absurd. Edit: I think the idea is absurd *to OP*. I'm not making a judgement one way or another. | E40: It is a cannibalism joke implying that they always get “chicken” after the dad has killed someone. | F40: Pizza had not been invented yet, which is why the situation does not really make sense historically. | G40: A four-panel comic shows a man in a helmet and formal clothing on a battlefield. He returns home holding a cooked chicken and tells his children that he brought dinner. The children complain that they are having chicken again and ask why he does not bring pizza next time, while the man looks upset. | H40: A four-panel comic shows a man in a helmet and formal clothing on a battlefield. He returns home holding a cooked chicken and tells his children that he brought dinner. The children complain that they are having chicken again and ask why he does not bring pizza next time, while the man looks upset. | I40: Exaggeration | J40: Dark Humor | K40: politics | L40: General knowledge
A41: 19bj5k2 | B41: Naomi | C41: Done | D41: Explaining 15 is 3 more than 12. It’s implying that the generations are getting dumber and dumber. | E41: A meme captioned "We're not gonna make it, are we?" with a photo of a Coca-Cola 15-pack box prominently labeled "3 MORE CANS THAN 12 PACK" with a green arrow pointing to the claim. | F41: Marketing math broken down into pre-kindergarten subtraction. | G41: Packaging copy written for an audience the manufacturer has clearly given up on. | H41: A meme captioned "We're not gonna make it, are we?" with a photo of a Coca-Cola 15-pack box prominently labeled "3 MORE CANS THAN 12 PACK" with a green arrow pointing to the claim. | I41: Sarcasm/Irony | J41: Exaggeration | K41: General knowledge | L41: Pop culture | M41: =IF(COUNTIF($A$2:A41, A41)>1, "Dublet", "OK") -> OK
A42: 19dbf08 | B42: Naomi | C42: Done | D42: It’s a zen expression. Before enlightenment, chop wood, carry water. After enlightenment, chop wood, carry water. Here’s a good explanation from the internet: Before Enlightenment, you hate your life. You chop wood and carry water, but secretly wish to get out of it all. You bear with these activities through habit and out of hopelessness, but you really wish you could do something else. In a way, you are a victim, a slave - the wood chops you and the water carries you, and there is no way to escape. This could go for eternity, it is like living in eternal hell. After Enlightenment, you are in harmony with the universe. You realized the emptiness of it all, so you see that there is nothing more important than chopping wood and carrying water. All activities are equalized, there is no preference, no discrimination. Because there is no "you", no ego, no personality, no being, no separate individuality - there is no conflict. No need to escape. No other bank to be reached, no Nirvana to seek. But also, because you have mastered your mind, you are not chopped by the wood and carried by the water anymore. You can flip your perspective at will. It is your choice to chop wood and carry water, and you live it in complete suchness and spontaneity. You are beyond the beyond. And even beyond "beyond the beyond". | E42: Chop wood, carry water — the only thing that changed was the beard. | F42: A two-panel meme labeled "Before Enlightenment" and "After Enlightenment." Both panels contain the same thought bubble showing an illustration of a man chopping wood and a photo of a man carrying water buckets on a shoulder pole. The top panel shows a crying, distressed wojak in the shower; the bottom panel shows a calm, bearded wojak in the shower. | G42: No matter what you do life is still is the same. | H42: A two-panel meme labeled "Before Enlightenment" and "After Enlightenment." Both panels contain the same thought bubble showing an illustration of a man chopping wood and a photo of a man carrying water buckets on a shoulder pole. The top panel shows a crying, distressed wojak in the shower; the bottom panel shows a calm, bearded wojak in the shower. | I42: Situational | J42: Comparison | K42: History/Mythology | L42: General knowledge | M42: =IF(COUNTIF($A$2:A42, A42)>1, "Dublet", "OK") -> OK
A43: 19egkxy | B43: Naomi | C43: Done | D43: There’s a first half to this comic, where the man goes to space and thinks that people would be nicer to each other if they could only see earth from that view. It’s a play on the idea that astronauts who see earth from space are given a better sense of perspective about how small the planet is and how our divides are artificially made. The man, however, immediately counteracts his own point by taking an elitist stance, thinking he’s morally enlightened and better than other people who haven’t seen earth from space. He had the revelation, but didn’t actually internalize its message. The comic then continues to show that people can be kind and loving to one another without ever seeing earth from space, showing that being kind is a choice you make. There’s nothing you have to do or see to make you be nicer to others, you just have to do it. People can see earth from space and not internalize kindness, people can never see earth from space and still be kind. | E43: The most insufferable bar question, answered with the gentlest possible white lie. | F43: Astronaut quietly choosing caregiving over flexing her resume at a party. | G43: A four-panel comic by Extra Fabulous Comics. In the first panel, a man at a bar asks a woman, "Have you ever seen Earth from space?" She replies "No," and he taunts "Ha! Loser!" The next panels show the woman driving home, arriving at a modest house, paying a babysitter, and finally sitting beside an elderly bedridden relative whom she tends to with a bowl of food, beside a framed photo on the wall depicting her as an astronaut. | H43: A four-panel comic by Extra Fabulous Comics. In the first panel, a man at a bar asks a woman, "Have you ever seen Earth from space?" She replies "No," and he taunts "Ha! Loser!" The next panels show the woman driving home, arriving at a modest house, paying a babysitter, and finally sitting beside an elderly bedridden relative whom she tends to with a bowl of food, beside a framed photo on the wall depicting her as an astronaut. | I43: Comparison | J43: Sarcasm/Irony | K43: Logical | L43: Social conventions | M43: =IF(COUNTIF($A$2:A43, A43)>1, "Dublet", "OK") -> OK
A44: 19eokbq | B44: Naomi | C44: Done | D44: In police interrogations they will get you food to reward you for cooperating and keep you talking, normally it's just McDonald's or a vending machine item. The fact that there are multiple KFC boxes and name brand drink for one person implies they're very happy with this person's cooperation level. | E44: Since he hasnt seen his friend in a long time they are cathing up and eating food. | F44: A child is being rewarded by their mom for telling on his siblings. | G44: A screenshot of a television playing the crime documentary show showing a blurred suspect in an interrogation room with a large spread of KFC fast food on the table, captioned "bro told on EVERYBODY" | H44: A screenshot of a television playing the crime documentary show showing a blurred suspect in an interrogation room with a large spread of KFC fast food on the table, captioned "bro told on EVERYBODY" | I44: Situational | J44: Dark Humor | K44: General knowledge | L44: politics | M44: =IF(COUNTIF($A$2:A44, A44)>1, "Dublet", "OK") -> OK
A45: 1actpx8 | B45: Sabrina | C45: Done | D45: the meme refers to cloudy and a chance of meatballs (movie): the main character is a scientist and sprayed on shoes when he was a kid, which he could never remove | E45: its exaggeration, as the meme presents an obviously unnecessary warning against using Flex Seal as footwear, thereby highlighting the absurdity of the situation. | F45: using Flex Seal as footwear is portrayed as undesirable, humorously justified by the unlikely scenario of falling meatballs from the sky. | G45: a snapchat picture showing a person holding a can of Flex Seal and their foot covered in a black substance, with the text ‘Flex seal shoe’ with the text underneath: "did the tales of falling meatballs not weigh on thine conscious". | H45: a snapchat picture showing a person holding a can of Flex Seal and their foot covered in a black substance, with the text ‘Flex seal shoe’ with the text underneath: "did the tales of falling meatballs not weigh on thine conscious". | I45: Sarcasm/Irony | J45: Surprise | K45: Hobby | L45: Pop culture | M45: =IF(COUNTIF($A$2:A45, A45)>1, "Dublet", "OK") -> OK
A46: 1aekqdo | B46: Naomi | C46: Done | D46: The Colt 1911 is a handgun that first entered service in… you guessed it! 1911. It saw service in both WW1 and WW2. It’s still a decent handgun even by todays standards, but it’s gained a cult following over the years, especially among boomers. When anyone brings up its shortcomings such as low magazine capacity, its weight, or that modern designs are typically more reliable, they say something along the lines of “muh two world wars!” Because it was on the winning side of both world wars. In the event of a third world war, it’s likely that the 1911 will see combat yet again. | E46: Nic Cage reads the news, Pedro Pascal reads the spec sheet. | F46: A two-panel meme using stills from The Unbearable Weight of Massive Talent. The top panel shows Nicolas Cage looking concerned with the caption "Seeing the world is on the brink of WW3," and the bottom panel shows Pedro Pascal grinning widely with the caption "The 1911." | G46: One man fears the apocalypse, the other already picked his sidearm. | H46: A two-panel meme using stills from The Unbearable Weight of Massive Talent. The top panel shows Nicolas Cage looking concerned with the caption "Seeing the world is on the brink of WW3," and the bottom panel shows Pedro Pascal grinning widely with the caption "The 1911." | I46: Sarcasm/Irony | J46: Comparison | K46: History/Mythology | L46: politics | M46: =IF(COUNTIF($A$2:A46, A46)>1, "Dublet", "OK") -> OK
A47: 1aexlbt | B47: Naomi | C47: Done | D47: It’s a fork bomb: Here’s a breakdown of what the command does: 1. () This defines a function named : (colon). 2. {} This indicates the start and end of the function’s body. 3. : (colon) inside the function: This is a no-op (no operation) placeholder. It doesn’t do anything but is necessary syntax for defining a function in Bash. 4. | This pipes the output of the function (which is nothing) to another instance of the function. 5. & This sends the command preceding it (another instance of the function) to run in the background. 6. ; This terminates the definition of the function. 7. : (colon) after the semicolon: This executes the function once. So, when you run this command, it defines a function that spawns a new instance of itself in an infinite loop, quickly exhausting system resources and causing the system to become unresponsive. The final : after the semicolon executes the function once to start the process. | E47: The cat is innocent; the bash fork bomb hiding in its collar is not. | F47: A house pet whose name is also a textbook denial-of-service attack. | G47: A meme with the caption "This cat's name is :(){ :|:& };: you should type his name on your linux's terminal" above a close-up photo of a black cat with bright yellow-green eyes staring straight at the camera. | H47: A meme with the caption "This cat's name is :(){ :|:& };: you should type his name on your linux's terminal" above a close-up photo of a black cat with bright yellow-green eyes staring straight at the camera. | I47: Wordplay | J47: Situational | K47: Technical | L47: Hobby | M47: =IF(COUNTIF($A$2:A47, A47)>1, "Dublet", "OK") -> OK
A48: 1af8odu | B48: Sabrina | C48: Done | D48: A teller is a person who works at the front desk of a bank. Teller is also a person's name; that person is one half of the magician duo Penn & Teller. On stage, Teller doesn't speak. Penn is the one who explains everything/talks to the crowd. The joke is that you expect the robber to be speaking to a bank teller. But he's actually speaking to the magician Teller who doesn't talk. That's why Penn comes in at the end to explain what's going on. | E48: Penn’s comment makes the scene funny because he already understands why the “teller” never answers. The silence is treated as typical behavior, not as fear or confusion | F48: A tweet-style image shows a fictional dialogue where a bank robber repeatedly asks a teller where the safe is. The teller gives no visible response, and the robber becomes confused. The final line says, “PENN: He always does this,” implying the teller is the magician Teller, who is known for staying silent. | G48: The robber is absurdly expecting a machine to respond like a person, which makes his frustration seem misplaced and cartoon-like. | H48: A tweet-style image shows a fictional dialogue where a bank robber repeatedly asks a teller where the safe is. The teller gives no visible response, and the robber becomes confused. The final line says, “PENN: He always does this,” implying the teller is the magician Teller, who is known for staying silent. | I48: Wordplay | J48: Sarcasm/Irony | K48: Pop culture | L48: Social conventions | M48: =IF(COUNTIF($A$2:A48, A48)>1, "Dublet", "OK") -> OK
A49: 1agsl73 | B49: Sabrina | C49: Done | D49: “One must imagine Sisyphus happy.” - Albert Camus | E49: It works because the phrase sounds like a rhyme, almost like “men are happy being crappy.” The wording makes it feel like a dumb little slogan, which is why it lands. | F49: It shows this contrast between old-school masculine men and the softer side of them writing poems for their lovers. They look tough, but they are still being romantic in a very dramatic way. | G49: The meme shows the text “Roses are red, Poems are sappy” above an image of a muscular figure pushing a large boulder up a rocky hill. | H49: The meme shows the text “Roses are red, Poems are sappy” above an image of a muscular figure pushing a large boulder up a rocky hill. | I49: Wordplay | J49: Surprise | K49: History/Mythology | L49: Logical | M49: =IF(COUNTIF($A$2:A49, A49)>1, "Dublet", "OK") -> OK
A50: 1ajx3sn | B50: Naomi | C50: Done | D50: It's a rickroll. Never gonna give you up, never gonna let you down | E50: A category so specific the answer reveals itself before any letter does. | F50: Toto's "Africa" auto-filling into every empty grid by default. | G50: A screenshot of an r/Funnymemes post captioned "Too easy" with a meme reading "Friend: You can't possibly guess a wheel of fortune puzzle with no letters / Me:" above a Wheel of Fortune board showing only blank tiles with no letters revealed, under the category "80's SONG LYRICS." | H50: A screenshot of an r/Funnymemes post captioned "Too easy" with a meme reading "Friend: You can't possibly guess a wheel of fortune puzzle with no letters / Me:" above a Wheel of Fortune board showing only blank tiles with no letters revealed, under the category "80's SONG LYRICS." | I50: Wordplay | J50: Comparison | K50: Pop culture | L50: Hobby | M50: =IF(COUNTIF($A$2:A50, A50)>1, "Dublet", "OK") -> OK
A51: 1ajzxfm | B51: Sabrina | C51: Done | D51: It’s kind of a weird joke that doesn’t make perfect sense, but here’s the intended meaning: 1. Many people might see something like 50/50 odds leading to 20 successes in a row and think the next one is more likely to be a failed surgery. Like how many people could flip a coin and get heads twice in a row, and be more likely to guess the next coinflip would be tails. Hence the nervous face. 2. A statistician would know that the success rate of each surgery is independent of all the other ones, so they wouldn’t be especially nervous theirs would go wrong. 3. A scientist might see 20 successes in a row for a surgery with a 50% survival rate and think “wow, this doctor must be really good at doing surgeries” | E51: The meme explains that normal people would choose this doctor because he has 50% success rate, where as mathematicians would be more sceptical and scientists would refrain from getting a surgery from this doctor. | F51: The meme is funny because it illustrates how different fields of process thoughts, it is funny because although most people would take the surgery, mathmaticians and scientists wouldn't because they have the knowledge to know that the probability of the surgery failing is very small despite the given numbers. | G51: A meme with text describing a doctor stating that a surgery has a 50% survival rate and that the last 20 patients survived. Below the text are three panels labeled ‘Normal people’, ‘Mathematician’, and ‘Scientist’, each showing a different face reacting to the statement. | H51: A meme with text describing a doctor stating that a surgery has a 50% survival rate and that the last 20 patients survived. Below the text are three panels labeled ‘Normal people’, ‘Mathematician’, and ‘Scientist’, each showing a different face reacting to the statement. | I51: Comparison | J51: Exaggeration | K51: Logical | L51: General knowledge | M51: =IF(COUNTIF($A$2:A51, A51)>1, "Dublet", "OK") -> OK
A52: 1amtoff | B52: Sabrina | C52: Done | D52: Amazon does not hire 12 year olds, and 12 year olds cannot drive. The potential panic this may cause whomever at Amazon, is hilarious. | E52: The humor arises from the unexpected implication that a well-known company such as Amazon employs a 12-year-old, which contradicts established social and legal norms, thereby creating a surprising and absurd scenario. | F52: A screenshot of a social media thread where a user says that Amazon hired their 12-year-old son, followed by a response from an Amazon customer service account asking for clarification, and a subsequent reply stating that the son is one of their drivers | G52: The humor stems from the company’s apparent unawareness of having employed an underage individual, leading to the implicit consequence that they would need to locate and terminate the employment, which highlights the absurdity of the situation. | H52: A screenshot of a social media thread where a user says that Amazon hired their 12-year-old son, followed by a response from an Amazon customer service account asking for clarification, and a subsequent reply stating that the son is one of their drivers | I52: Incongruity | J52: Sarcasm/Irony | K52: General knowledge | L52: politics | M52: =IF(COUNTIF($A$2:A52, A52)>1, "Dublet", "OK") -> OK
... A175: 1fl51f0 | B175: Naomi | C175: Done | D175: "It signals that the car is driven by a gay couple looking for a big, hairy threesome partner" | E175: Its generally a bad idea to have custom made license plates | F175: The lady driving in from of OP, is presumably bad at driving and has caused an accident | G175: Its funny because its hard to read the license plate | H175: The lady driving in from of OP, is presumably bad at driving and has caused an accident | I175: Wordplay | J175: Situational | K175: Social conventions | L175: Logical | M175: =IF(COUNTIF($A$2:A175, A175)>1, "Dublet", "OK") -> OK
A176: 1flb4nk | B176: Sabrina | C176: Done | D176: The show being referenced is the mockumentary Cunk on Earth, where the titular narrator humorously misinterprets history. The Romans left a lot from their history, including pottery fragments (which broke due to the long time period), which Cunk humorously says is caused by their clumsiness. | E176: A social media post shows a woman standing in front of ancient ruins. Below it, another post says that based on the amount of pottery fragments, the Roman Empire may have been the clumsiest empire in history. | F176: Materials have changed a lot since ancient times, so pottery today can last much longer than pottery from the Roman Empire. | G176: Someone probably broke the pottery on purpose just to mess with the Roman Empire. | H176: A social media post shows a woman standing in front of ancient ruins. Below it, another post says that based on the amount of pottery fragments, the Roman Empire may have been the clumsiest empire in history. | I176: Surprise | J176: Exaggeration | K176: History/Mythology | L176: Logical | M176: =IF(COUNTIF($A$2:A206, A176)>1, "Dublet", "OK") -> OK
A177: 1fm0tjo | B177: Sabrina | C177: Done | D177: Someone feels old because they remembered Y2K was a thing. | E177: Obviously no one can live for 3000 years. | F177: Back then people thought not turning off the PC would break it. | G177: A meme showing a sticker reading “REMEMBER Turn your computer off before midnight on 12/31/99” above an image of a man with the caption “I was there. 3,000 years ago…” | H177: A meme showing a sticker reading “REMEMBER Turn your computer off before midnight on 12/31/99” above an image of a man with the caption “I was there. 3,000 years ago…” | I177: Exaggeration | J177: Situational | K177: Logical | L177: Social conventions | M177: =IF(COUNTIF($A$2:A177, A177)>1, "Dublet", "OK") -> OK
A178: 1fo91u1 | B178: Sabrina | C178: Done | D178: The Logo designer normally charges 350$ But the person asking for the logo has a budget of 800$ 800$ is more dollars than the 350$, this is an important fact which can be easily overlooked. So just about as the logo desinger was to send their message they see this. And after doing a bit of math and self refelection they think to themselves. "hmm, I could also charge 800$ as that is more than 350$" Which will allow the logo desinger to buy more peanuts. Peanuts are tasty. Also shrek is there for the 'hold on a moment' thing and obviously for the sex appeal. | E178: It’s funny because the offer is much lower than the original price. | F178: It’s funny because the buyer sent the message to the wrong person. | G178: A screenshot of a chat where a person asks for a logo price, states a budget of $800, and a reply is typed “Logo design price is $350,” followed by an image of Shrek smiling. | H178: A screenshot of a chat where a person asks for a logo price, states a budget of $800, and a reply is typed “Logo design price is $350,” followed by an image of Shrek smiling. | I178: Situational | J178: Sarcasm/Irony | K178: Logical | L178: Social conventions | M178: =IF(COUNTIF($A$2:A178, A178)>1, "Dublet", "OK") -> OK
A179: 1fq1qb9 | B179: Naomi | C179: Done | D179: The pain of regret cuts deeper than the pain of discipline. | E179: A motivational-style illustration titled "PAIN" showing two cartoon kitchen knives side by side. The left knife, labeled "DISCIPLINE," has a mostly clean blade with a small amount of red at the base. The right knife, labeled "REGRET," is fully coated in red across the entire blade. | F179: Inspirational graphic that accidentally moonlights as crime-scene evidence. | G179: A motivational poster taking the metaphor too literally, with cutlery. | H179: A motivational-style illustration titled "PAIN" showing two cartoon kitchen knives side by side. The left knife, labeled "DISCIPLINE," has a mostly clean blade with a small amount of red at the base. The right knife, labeled "REGRET," is fully coated in red across the entire blade. | I179: Wordplay | J179: Comparison | K179: Logical | L179: General knowledge | M179: =IF(COUNTIF($A$2:A179, A179)>1, "Dublet", "OK") -> OK
A180: 1fs6ndo | B180: Sabrina | C180: Done | D180: Tyranids avoid two things , demon and necron. Tbf thé latter are probably a better news than the nids | E180: Something bad is happening, yet the soldier is still smiling. | F180: At first it seems like bad news, but then he realizes it’s actually good. | G180: A three-panel meme showing a soldier in armor with text: “A Tyranid fleet is approaching the system,” followed by two panels both stating “It ignores your planet,” with the soldier’s facial expression changing. | H180: A three-panel meme showing a soldier in armor with text: “A Tyranid fleet is approaching the system,” followed by two panels both stating “It ignores your planet,” with the soldier’s facial expression changing. | I180: Comparison | J180: Dark Humor | K180: Hobby | L180: Logical | M180: =IF(COUNTIF($A$2:A180, A180)>1, "Dublet", "OK") -> OK
A181: 1fs7uqa | B181: Sabrina | C181: Done | D181: News anchor Wolf Blitzer tweeted a photo of himself out having drinks on a Sunday, July 21st. That happened to be the same Sunday that Biden made the historic decision to drop out of the presidential race, about an hour or so later, and so Blitzer seemingly was asked to come in to work again for this breaking news story. Other people are joking that if he hadn't checked his email, he would have been able to continue enjoying his day off instead of having it interrupted and having to go in to work. | E181: One moment he is happily enjoying beers with his friends on his day off, and the next he finds out through his work email that he has been fired. If he had just ignored the email, he could have delayed knowing and kept enjoying the day a little longer. | F181: He was just having drinks on his day off, and then somehow ended up on the news for being reckless. So honestly, maybe he should have checked his work email, because the firing notice would have given him a heads-up that things were already going downhill. | G181: A meme says, “Never check your work email on a day off.” It shows one photo of an older man smiling with a drink and another photo of the same man looking serious on a news broadcast. | H181: A meme says, “Never check your work email on a day off.” It shows one photo of an older man smiling with a drink and another photo of the same man looking serious on a news broadcast. | I181: Surprise | J181: Exaggeration | K181: politics | L181: Social conventions | M181: =IF(COUNTIF($A$2:A181, A181)>1, "Dublet", "OK") -> OK
A182: 1fssuxj | B182: Naomi | C182: Done | D182: There is no I in nothing or again. He made the letter I not exist anymore. | E182: Its a play on percieved reality and meta that you can never be sure if anything is ever real. | F182: Its implying that we no longer exost since when you read you are I. | G182: In this four-panel comic, a character tells a genie, "I wish I didn't exist," to which the genie responds, "Granted." After a "POOF!" the character observes that "Nothng Changed," and the genie tells them to "Look Agan," revealing that the letter "i" has been removed from the dialogue.' | H182: In this four-panel comic, a character tells a genie, "I wish I didn't exist," to which the genie responds, "Granted." After a "POOF!" the character observes that "Nothng Changed," and the genie tells them to "Look Agan," revealing that the letter "i" has been removed from the dialogue. | I182: Wordplay | J182: Sarcasm/Irony | K182: Logical | L182: General knowledge | M182: =IF(COUNTIF($A$2:A182, A182)>1, "Dublet", "OK") -> OK
A183: 1fst6nb | B183: Sabrina | C183: Done | D183: Yeah its a political joke, the neighbours have taken a part of the other person's garden just like Russia has taken parts of Ukraine. Hopefully that helps. | E183: It plays on the stereotype that Russians tend to be reserved rather than overly talkative. | F183: There’s an implicit absurdity in someone openly identifying as Russian to their neighbors in an American setting, where that isn’t particularly common. | G183: Drawing of a man standing by a fence talking to two neighbors inside a yard; a speech bubble says: “No, we’ve never had Russian neighbours. You are the first.” | H183: Drawing of a man standing by a fence talking to two neighbors inside a yard; a speech bubble says: “No, we’ve never had Russian neighbours. You are the first.” | I183: Comparison | J183: Sarcasm/Irony | K183: politics | L183: Logical | M183: =IF(COUNTIF($A$2:A183, A183)>1, "Dublet", "OK") -> OK
A184: 1ftatdh | B184: Naomi | C184: Done | D184: Can’t be 100% sure, but I think that’s meant to be Joseph Smith, founder of Mormonism. In Mormonism, America is the true Promised Land, not Israel. Or something like that, I’m not religious. Edit: Great thanks to everyone who’s provided corrections and specifics! Everyone should upvote them | E184: Joseph Smith showing up in the comments like "way ahead of you." | F184: A screenshot of a tweet from "Enhanced Interrogated Poet" quote-tweeting a post from "frye" (@__frye) reading "they should invent a Holy Land that's not in the middle east." The quoted image is a portrait painting of Joseph Smith, founder of the Latter-day Saint movement, with a blank speech bubble pointing at him. | G184: 19th-century pre-emptive response to a 2024 take. | H184: A screenshot of a tweet from "Enhanced Interrogated Poet" quote-tweeting a post from "frye" (@__frye) reading "they should invent a Holy Land that's not in the middle east." The quoted image is a portrait painting of Joseph Smith, founder of the Latter-day Saint movement, with a blank speech bubble pointing at him. | I184: Exaggeration | J184: Comparison | K184: History/Mythology | L184: General knowledge | M184: =IF(COUNTIF($A$2:A184, A184)>1, "Dublet", "OK") -> OK
A185: 1ftdy3c | B185: Sabrina | C185: Done | D185: "It's missing the punchline. The other muffin screams 'Oh my god, a talking muffin!'" | E185: The muffin is screaming because theyre in a hot oven | F185: Theyre screamin in the oven because theyre coming alive | G185: A photo shows a person holding a wrapped object or package with printed text on it. The visible text says, “Two muffins were sitting in an oven. One says ‘Geez, it’s hot in here.’ The other screams.” Above the photo, there is a caption that says, “what kind of joke is this.” | H185: A photo shows a person holding a wrapped object or package with printed text on it. The visible text says, “Two muffins were sitting in an oven. One says ‘Geez, it’s hot in here.’ The other screams.” Above the photo, there is a caption that says, “what kind of joke is this.” | I185: Surprise | J185: Sarcasm/Irony | K185: Logical | L185: Social conventions | M185: =IF(COUNTIF($A$2:A185, A185)>1, "Dublet", "OK") -> OK
A186: 1fu3pp1 | B186: Sabrina | C186: Done | D186: that is way too good for a school computer. it's clearly for gaming | E186: The humor comes from a child demonstrating unexpectedly advanced knowledge. | F186: The phrasing appears not making sense, which creates the comedic effect. | G186: Four-panel meme: top text shows a mother asking for a PC for school and a son listing high-end specs; bottom panels show Shrek smiling. | H186: Four-panel meme: top text shows a mother asking for a PC for school and a son listing high-end specs; bottom panels show Shrek smiling. | I186: Incongruity | J186: Situational | K186: Technical | L186: Hobby | M186: =IF(COUNTIF($A$2:A186, A186)>1, "Dublet", "OK") -> OK
A187: 1fuxrbx | B187: Sabrina | C187: Done | D187: The numbers when pressed will correlate to different letters. For example, pressing 2 will give you A, but pressing 22 will give you B, 222 giving you C, and so on. This pattern of numbers spells, "It was me Dio!" Which is a reference to the anime Jojo's Bizarre Adventure. The line is said by the main antagonist, named Dio Brando. | E187: The joke lies in how it presents itself as completely ordinary, even though it’s framed as something unusual. | F187: That old Nokia triggers nostalgia, which is what makes it amusing. | G187: Image of an old mobile phone keypad with numbers and letters; below it is the sequence: “4448 927777 633 3444666”. | H187: Image of an old mobile phone keypad with numbers and letters; below it is the sequence: “4448 927777 633 3444666”. | I187: Wordplay | J187: Surprise | K187: Hobby | L187: Pop culture | M187: =IF(COUNTIF($A$2:A187, A187)>1, "Dublet", "OK") -> OK
...

Sheet PAnnotations
A1: File | B1: Assigned_to | C1: Status | D1: Correct answer | E1: Literal_Description | F1: Humor Style | G1: Humor style secondary | H1: Contextual Knowledge | I1: Contextual Knowledge secondary | J1: Partner name | K1: Status | L1: Partner: Humor Style | M1: Partner: Humor style secondary | N1: Partner: Contextual Knowledge | O1: Partner: Contextual Knowledge secondary | P1: Humor primary match | Q1: Humor full label-set overlap | R1: Context primary match | S1: Context full label-set overlap | T1: Humor partial overlap | U1: Context partial overlap
A2: 1actpx8 | B2: Sabrina | C2: Done | D2: the meme refers to cloudy and a chance of meatballs (movie): the main character is a scientist and sprayed on shoes when he was a kid, which he could never remove | E2: a snapchat picture showing a person holding a can of Flex Seal and their foot covered in a black substance, with the text ‘Flex seal shoe’ with the text underneath: "did the tales of falling meatballs not weigh on thine conscious". | F2: Sarcasm/Irony | G2: Surprise | H2: Hobby | I2: Pop culture | J2: Naomi | K2: Done | L2: Sarcasm/Irony | M2: Situational | N2: Hobby | O2: Pop culture | P2: =IF(F2=L2,1,0) -> 1 | Q2: =IF(OR(AND(F2=L2,G2=M2),AND(F2=M2,G2=L2)),1,0) -> 0 | R2: =IF(H2=N2,1,0) -> 1 | S2: =IF(OR(AND(H2=N2,I2=O2),AND(H2=O2,I2=N2)),1,0) -> 1 | T2: =IF(OR(F2=L2,F2=M2,G2=L2,G2=M2),1,0) -> 1 | U2: =IF(OR(H2=N2,H2=O2,I2=N2,I2=O2),1,0) -> 1
A3: 1amtoff | B3: Sabrina | C3: Done | D3: Amazon does not hire 12 year olds, and 12 year olds cannot drive. The potential panic this may cause whomever at Amazon, is hilarious. | E3: A screenshot of a social media thread where a user says that Amazon hired their 12-year-old son, followed by a response from an Amazon customer service account asking for clarification, and a subsequent reply stating that the son is one of their drivers | F3: Incongruity | G3: Sarcasm/Irony | H3: General knowledge | I3: politics | J3: Naomi | K3: Done | L3: Incongruity | M3: Sarcasm/Irony | N3: General knowledge | O3: politics | P3: =IF(F3=L3,1,0) -> 1 | Q3: =IF(OR(AND(F3=L3,G3=M3),AND(F3=M3,G3=L3)),1,0) -> 1 | R3: =IF(H3=N3,1,0) -> 1 | S3: =IF(OR(AND(H3=N3,I3=O3),AND(H3=O3,I3=N3)),1,0) -> 1 | T3: =IF(OR(F3=L3,F3=M3,G3=L3,G3=M3),1,0) -> 1 | U3: =IF(OR(H3=N3,H3=O3,I3=N3,I3=O3),1,0) -> 1
A4: 1b7unh0 | B4: Sabrina | C4: Done | D4: He would probably also be confused why they had built a second Memphis | E4: A meme divided into two sections labeled “Women with a time machine” and “Men with a time machine.” The top shows a woman pointing a gun at Henry Ford. The bottom shows a man speaking to an ancient Egyptian figure in front of a pyramid, with text about a modern glass pyramid in Memphis containing a Bass Pro Shop. | F4: Comparison | G4: Exaggeration | H4: History/Mythology | I4: Logical | J4: Naomi | K4: Done | L4: Comparison | M4: Exaggeration | N4: History/Mythology | O4: Logical | P4: =IF(F4=L4,1,0) -> 1 | Q4: =IF(OR(AND(F4=L4,G4=M4),AND(F4=M4,G4=L4)),1,0) -> 1 | R4: =IF(H4=N4,1,0) -> 1 | S4: =IF(OR(AND(H4=N4,I4=O4),AND(H4=O4,I4=N4)),1,0) -> 1 | T4: =IF(OR(F4=L4,F4=M4,G4=L4,G4=M4),1,0) -> 1 | U4: =IF(OR(H4=N4,H4=O4,I4=N4,I4=O4),1,0) -> 1
A5: 1bikyy1 | B5: Sabrina | C5: Done | D5: The math is a little off, but the gist of it is that the grand canyon took a long *long* time to get to its current state, but, at some point in the very distant past, it would've started out as a small stream, as depicted in the meme. So, the joke is that the Flintstones were around a long time ago when the Grand Canyon was still just a little stream. | E5: A meme with the text “So that's the Grand Canyon, huh?” followed by “– The Flintstones,” showing a cartoon scene of characters standing near a narrow canyon with a small stream running through it. | F5: Incongruity | G5: Surprise | H5: History/Mythology | I5: General knowledge | J5: Naomi | K5: Done | L5: Incongruity | M5: Surprise | N5: Hobby | O5: Technical | P5: =IF(F5=L5,1,0) -> 1 | Q5: =IF(OR(AND(F5=L5,G5=M5),AND(F5=M5,G5=L5)),1,0) -> 1 | R5: =IF(H5=N5,1,0) -> 0 | S5: =IF(OR(AND(H5=N5,I5=O5),AND(H5=O5,I5=N5)),1,0) -> 0 | T5: =IF(OR(F5=L5,F5=M5,G5=L5,G5=M5),1,0) -> 1 | U5: =IF(OR(H5=N5,H5=O5,I5=N5,I5=O5),1,0) -> 0
A6: 1bmtc5u | B6: Sabrina | C6: Done | D6: He likes big butts and he cannot lie. | E6: A black-and-white cartoon of a courtroom scene where a judge asks a witness to swear to tell the truth. The witness, a woman standing at the stand, responds that it will not be necessary. Several people are seated in the courtroom observing the exchange. | F6: Incongruity | G6: Exaggeration | H6: Social conventions | I6: Pop culture | J6: Naomi | K6: Done | L6: Situational | M6: Incongruity | N6: Social conventions | O6: Pop culture | P6: =IF(F6=L6,1,0) -> 0 | Q6: =IF(OR(AND(F6=L6,G6=M6),AND(F6=M6,G6=L6)),1,0) -> 0 | R6: =IF(H6=N6,1,0) -> 1 | S6: =IF(OR(AND(H6=N6,I6=O6),AND(H6=O6,I6=N6)),1,0) -> 1 | T6: =IF(OR(F6=L6,F6=M6,G6=L6,G6=M6),1,0) -> 1 | U6: =IF(OR(H6=N6,H6=O6,I6=N6,I6=O6),1,0) -> 1
A7: 1c6zoan | B7: Sabrina | C7: Done | D7: That's a (slightly edited) picture of Todd Howard, the director, executive producer, and public spokesperson for Bethesda Games. He lead development on all the Elder Scrolls games (Skyrim), Starfield, and Fallout 3, 4, and 76. Recently the Fallout TV series was released and it featured an event that happened in one of the endings of "Fallout New Vegas," a game published but *not developed* by Bethesda. But the event in question happens in different years in each of New Vegas and the TV show. Because of this Todd was asked recently whether New Vegas or the TV show is canon to the series at large, and if New Vegas is, which ending. His response was "all of Fallout is canon." Which doesn't really answer any questions or make sense. | E7: A screenshot of a social media post showing a dialogue about inconsistencies in a fictional storyline, mentioning “Todd” and “New Vegas,” followed by a repeated response stating “All of it.” Below the text is an image of Todd. | F7: Incongruity | G7: Sarcasm/Irony | H7: Pop culture | I7: Hobby | J7: Naomi | K7: Done | L7: Incongruity | M7: Sarcasm/Irony | N7: Pop culture | O7: Hobby | P7: =IF(F7=L7,1,0) -> 1 | Q7: =IF(OR(AND(F7=L7,G7=M7),AND(F7=M7,G7=L7)),1,0) -> 1 | R7: =IF(H7=N7,1,0) -> 1 | S7: =IF(OR(AND(H7=N7,I7=O7),AND(H7=O7,I7=N7)),1,0) -> 1 | T7: =IF(OR(F7=L7,F7=M7,G7=L7,G7=M7),1,0) -> 1 | U7: =IF(OR(H7=N7,H7=O7,I7=N7,I7=O7),1,0) -> 1
A8: 1cehmmt | B8: Naomi | C8: Done | D8: He looks very much like Hugh Laurie. | E8: It is a screeshot of an internet article with the title of "Russian Plumber Doesn't Know Why People Stare At Him On The Street" the phot below the caption shows a middle aged caucasian male with a tired expression. | F8: Situational | G8: Comparison | H8: Pop culture | I8: Hobby | J8: Sabrina | K8: Done | L8: Comparison | M8: Surprise | N8: Pop culture | O8: Hobby | P8: =IF(F8=L8,1,0) -> 0 | Q8: =IF(OR(AND(F8=L8,G8=M8),AND(F8=M8,G8=L8)),1,0) -> 0 | R8: =IF(H8=N8,1,0) -> 1 | S8: =IF(OR(AND(H8=N8,I8=O8),AND(H8=O8,I8=N8)),1,0) -> 1 | T8: =IF(OR(F8=L8,F8=M8,G8=L8,G8=M8),1,0) -> 1 | U8: =IF(OR(H8=N8,H8=O8,I8=N8,I8=O8),1,0) -> 1
A9: 1cgcw31 | B9: Naomi | C9: Done | D9: Its a reference to a trend on TikTok where people will ask women if they would feel safer being alone in the woods with a bear or a random man and they almost always choose the bear. Basically the idea is that the bear will be pretty much harmless if you leave it alone vs a man could have nefarious intent with no provocation. | E9: It shows a man speaking with the caption "if you don't understand why women are choosing the bear... you are probably part of the reason they are choosing the bear"and the llama reacting with a gaping sigh. | F9: Exaggeration | G9: Sarcasm/Irony | H9: Pop culture | I9: meme | J9: Sabrina | K9: Done | L9: Exaggeration | M9: Sarcasm/Irony | N9: Pop culture | O9: meme | P9: =IF(F9=L9,1,0) -> 1 | Q9: =IF(OR(AND(F9=L9,G9=M9),AND(F9=M9,G9=L9)),1,0) -> 1 | R9: =IF(H9=N9,1,0) -> 1 | S9: =IF(OR(AND(H9=N9,I9=O9),AND(H9=O9,I9=N9)),1,0) -> 1 | T9: =IF(OR(F9=L9,F9=M9,G9=L9,G9=M9),1,0) -> 1 | U9: =IF(OR(H9=N9,H9=O9,I9=N9,I9=O9),1,0) -> 1
A10: 1eae89f | B10: Naomi | C10: Done | D10: In one possible ending of Bloodborne, the protagonist becomes an eldritch squid creature. | E10: It shows a line of somber men walking in a single file line into a an upside cover of the game Bloodborne and leaving the other side of the cover is a line of squids. | F10: Exaggeration | G10: Comparison | H10: Hobby | I10: Logical | J10: Sabrina | K10: Done | L10: Exaggeration | M10: Comparison | N10: Hobby | O10: Logical | P10: =IF(F10=L10,1,0) -> 1 | Q10: =IF(OR(AND(F10=L10,G10=M10),AND(F10=M10,G10=L10)),1,0) -> 1 | R10: =IF(H10=N10,1,0) -> 1 | S10: =IF(OR(AND(H10=N10,I10=O10),AND(H10=O10,I10=N10)),1,0) -> 1 | T10: =IF(OR(F10=L10,F10=M10,G10=L10,G10=M10),1,0) -> 1 | U10: =IF(OR(H10=N10,H10=O10,I10=N10,I10=O10),1,0) -> 1
A11: 1iw42ka | B11: Naomi | C11: Done | D11: Grimes met Elon Musk at Met gala 2018 , leading to their relationship . Many people believe things would have been better if Grimes and Musk had never met . | E11: It is a screeenshot of a tweet showing a meme with the top portion titled "Boys with the time Machine" and one male face saying "im your grandson" and he other one replies "wow" the lower portion of the meme is titled "Girls with the time machine" and a group of females speaking to a photo of Grimes with the caption "do not go to the 2018 Met Gala" | F11: Exaggeration | G11: Comparison | H11: Pop culture | I11: politics | J11: Sabrina | K11: Done | L11: Exaggeration | M11: Comparison | N11: Pop culture | O11: Social conventions | P11: =IF(F11=L11,1,0) -> 1 | Q11: =IF(OR(AND(F11=L11,G11=M11),AND(F11=M11,G11=L11)),1,0) -> 1 | R11: =IF(H11=N11,1,0) -> 1 | S11: =IF(OR(AND(H11=N11,I11=O11),AND(H11=O11,I11=N11)),1,0) -> 0 | T11: =IF(OR(F11=L11,F11=M11,G11=L11,G11=M11),1,0) -> 1 | U11: =IF(OR(H11=N11,H11=O11,I11=N11,I11=O11),1,0) -> 1
