Workbook

Sheet Annotations
A1: File | B1: Assigned_to | C1: Status | D1: Correct answer | E1: Explanation 1 | F1: Explanation 2 | G1: Explanation 3 | H1: Literal_Description | I1: Humor Style | J1: Humor style secondary | K1: Contextual Knowledge | L1: Contextual Knowledge secondary | M1: Duplicate check
A2: 1actpx8 | B2: Sabrina | C2: Done | D2: the meme refers to cloudy and a chance of meatballs (movie): the main character is a scientist and sprayed on shoes when he was a kid, which he could never remove | E2: its exaggeration, as the meme presents an obviously unnecessary warning against using Flex Seal as footwear, thereby highlighting the absurdity of the situation. | F2: using Flex Seal as footwear is portrayed as undesirable, humorously justified by the unlikely scenario of falling meatballs from the sky. | G2: a snapchat picture showing a person holding a can of Flex Seal and their foot covered in a black substance, with the text ‘Flex seal shoe’ with the text underneath: "did the tales of falling meatballs not weigh on thine conscious". | H2: a snapchat picture showing a person holding a can of Flex Seal and their foot covered in a black substance, with the text ‘Flex seal shoe’ with the text underneath: "did the tales of falling meatballs not weigh on thine conscious". | I2: Sarcasm/Irony | J2: Surprise | K2: Hobby | L2: Logical | M2: =IF(COUNTIF($A$2:A2, A2)>1, "Dublet", "OK") -> OK
A3: 1af8odu | B3: Sabrina | C3: Done | D3: A teller is a person who works at the front desk of a bank. Teller is also a person's name; that person is one half of the magician duo Penn & Teller. On stage, Teller doesn't speak. Penn is the one who explains everything/talks to the crowd. The joke is that you expect the robber to be speaking to a bank teller. But he's actually speaking to the magician Teller who doesn't talk. That's why Penn comes in at the end to explain what's going on. | E3: Penn’s comment makes the scene funny because he already understands why the “teller” never answers. The silence is treated as typical behavior, not as fear or confusion | F3: A tweet-style image shows a fictional dialogue where a bank robber repeatedly asks a teller where the safe is. The teller gives no visible response, and the robber becomes confused. The final line says, “PENN: He always does this,” implying the teller is the magician Teller, who is known for staying silent. | G3: The robber is absurdly expecting a machine to respond like a person, which makes his frustration seem misplaced and cartoon-like. | H3: A tweet-style image shows a fictional dialogue where a bank robber repeatedly asks a teller where the safe is. The teller gives no visible response, and the robber becomes confused. The final line says, “PENN: He always does this,” implying the teller is the magician Teller, who is known for staying silent. | I3: Wordplay | J3: Sarcasm/Irony | K3: Pop culture | L3: Social conventions | M3: =IF(COUNTIF($A$2:A3, A3)>1, "Dublet", "OK") -> OK
A4: 1ajzxfm | B4: Sabrina | C4: Done | D4: It’s kind of a weird joke that doesn’t make perfect sense, but here’s the intended meaning: 1. Many people might see something like 50/50 odds leading to 20 successes in a row and think the next one is more likely to be a failed surgery. Like how many people could flip a coin and get heads twice in a row, and be more likely to guess the next coinflip would be tails. Hence the nervous face. 2. A statistician would know that the success rate of each surgery is independent of all the other ones, so they wouldn’t be especially nervous theirs would go wrong. 3. A scientist might see 20 successes in a row for a surgery with a 50% survival rate and think “wow, this doctor must be really good at doing surgeries” | E4: The meme explains that normal people would choose this doctor because he has 50% success rate, where as mathematicians would be more sceptical and scientists would refrain from getting a surgery from this doctor. | F4: The meme is funny because it illustrates how different fields of process thoughts, it is funny because although most people would take the surgery, mathmaticians and scientists wouldn't because they have the knowledge to know that the probability of the surgery failing is very small despite the given numbers. | G4: A meme with text describing a doctor stating that a surgery has a 50% survival rate and that the last 20 patients survived. Below the text are three panels labeled ‘Normal people’, ‘Mathematician’, and ‘Scientist’, each showing a different face reacting to the statement. | H4: A meme with text describing a doctor stating that a surgery has a 50% survival rate and that the last 20 patients survived. Below the text are three panels labeled ‘Normal people’, ‘Mathematician’, and ‘Scientist’, each showing a different face reacting to the statement. | I4: Comparison | J4: Exaggeration | K4: Logical | L4: General knowledge | M4: =IF(COUNTIF($A$2:A4, A4)>1, "Dublet", "OK") -> OK
A5: 1amtoff | B5: Sabrina | C5: Done | D5: Amazon does not hire 12 year olds, and 12 year olds cannot drive. The potential panic this may cause whomever at Amazon, is hilarious. | E5: The humor arises from the unexpected implication that a well-known company such as Amazon employs a 12-year-old, which contradicts established social and legal norms, thereby creating a surprising and absurd scenario. | F5: A screenshot of a social media thread where a user says that Amazon hired their 12-year-old son, followed by a response from an Amazon customer service account asking for clarification, and a subsequent reply stating that the son is one of their drivers | G5: The humor stems from the company’s apparent unawareness of having employed an underage individual, leading to the implicit consequence that they would need to locate and terminate the employment, which highlights the absurdity of the situation. | H5: A screenshot of a social media thread where a user says that Amazon hired their 12-year-old son, followed by a response from an Amazon customer service account asking for clarification, and a subsequent reply stating that the son is one of their drivers | I5: Incongruity | J5: Sarcasm/Irony | K5: General knowledge | L5: Social conventions | M5: =IF(COUNTIF($A$2:A5, A5)>1, "Dublet", "OK") -> OK
A6: 1aoxsw3 | B6: Sabrina | C6: Done | D6: Deer run in circles as a defense mechanism against predators ants run in circles because an ant has to turn around & left a pheromone trail in a circle, so the ants will die. it’s very sad. | E6: The humor arises from a contrast in perception, where similar circular movement is framed as unsettling in deer but appealing in ants. | F6: The humor stems from anthropomorphic framing, as deer and ants are depicted as exhibiting human-like reactions when observing animals moving in circles. | G6: “A meme with the caption ‘Animals running in circles is so cool’ at the top, followed by two images of animals arranged in circular formations. Below the images are two panels with illustrated faces, labeled ‘Deers’ on the left and ‘Ants’ on the right, each showing a different facial expression.” | H6: “A meme with the caption ‘Animals running in circles is so cool’ at the top, followed by two images of animals arranged in circular formations. Below the images are two panels with illustrated faces, labeled ‘Deers’ on the left and ‘Ants’ on the right, each showing a different facial expression.” | I6: Comparison | J6: Situational | K6: Technical | L6: General knowledge | M6: =IF(COUNTIF($A$2:A6, A6)>1, "Dublet", "OK") -> OK
A7: 1asrnb3 | B7: Sabrina | C7: Done | D7: The black car is the Impala (aka “Metallicar”/“Baby”) from *Supernatural*, a show about two brothers who hunt down paranormal phenomena like ghosts, demons, etc. The Mystery Machine, of course, is Scooby Doo and the Scooby Gang, who hunt down ghosts and other various monsters. If they’re both in the same place, some haunted stuff is going down. | E7: Incongruity between the claim that the location is haunted and the absence of any visible supernatural elements, resulting in a confusing and unexpected situation. | F7: The humor stems from a cultural association between the presence of suspicious-looking vehicles and the suggestion of unusual activity, which contrasts with the otherwise ordinary setting. | G7: A meme with the text “oh this place is HAUNTED haunted” at the top, showing a black car parked in front of a colorful van resembling the Scooby-Doo “Mystery Machine” in a parking lot. | H7: A meme with the text “oh this place is HAUNTED haunted” at the top, showing a black car parked in front of a colorful van resembling the Scooby-Doo “Mystery Machine” in a parking lot. | I7: Exaggeration | J7: Comparison | K7: Pop culture | L7: Hobby | M7: =IF(COUNTIF($A$2:A7, A7)>1, "Dublet", "OK") -> OK
A8: 1aya611 | B8: Sabrina | C8: Done | D8: Alabama ruled that frozen embryos count as live children, so this couple is claiming their 3 live children and 5 frozen embryos as 8 total children for tax purposes | E8: The humor arises from the unexpected implication that the parents to the children are experimenting on them in a lab they have at home | F8: The couple tries to claim more children for tax benefits, but claiming 'children in the lab' creates absurdity which makes the situation funny | G8: A meme showing a couple sitting in an office labeled “Tax Services,” speaking to a man behind a desk. One person says “We’re claiming 8 kids…” and the other adds “3 at home and 5 in the lab.” | H8: A meme showing a couple sitting in an office labeled “Tax Services,” speaking to a man behind a desk. One person says “We’re claiming 8 kids…” and the other adds “3 at home and 5 in the lab.” | I8: Sarcasm/Irony | J8: Exaggeration | K8: Social conventions | L8: Logical | M8: =IF(COUNTIF($A$2:A8, A8)>1, "Dublet", "OK") -> OK
A9: 1b03bqv | B9: Sabrina | C9: Done | D9: we's making up states to mess em up badly | E9: The state is relatively small and is therefore often overlooked or difficult to recall. | F9: the stereotype that many Americans are unable to identify all U.S. states, implying that they would fail the task presented. | G9: A map of the United States showing state borders, with one state highlighted in yellow and a caption asking viewers to identify it. | H9: A map of the United States showing state borders, with one state highlighted in yellow and a caption asking viewers to identify it. | I9: Incongruity | J9: Sarcasm/Irony | K9: politics | L9: General knowledge | M9: =IF(COUNTIF($A$2:A9, A9)>1, "Dublet", "OK") -> OK
A10: 1b7unh0 | B10: Sabrina | C10: Done | D10: He would probably also be confused why they had built a second Memphis | E10: The humor arises from a stereotypical contrast suggesting that men would use time travel to carry out significant historical interventions, whereas women are portrayed as being motivated by the desire to see Cleopatra in person. | F10: The humor stems from a reversed stereotypical framing in which women are depicted as pursuing significant historical interventions, while men are portrayed as being motivated by the desire to see Cleopatra in person. | G10: A meme divided into two sections labeled “Women with a time machine” and “Men with a time machine.” The top shows a woman pointing a gun at Henry Ford. The bottom shows a man speaking to an ancient Egyptian figure in front of a pyramid, with text about a modern glass pyramid in Memphis containing a Bass Pro Shop. | H10: A meme divided into two sections labeled “Women with a time machine” and “Men with a time machine.” The top shows a woman pointing a gun at Henry Ford. The bottom shows a man speaking to an ancient Egyptian figure in front of a pyramid, with text about a modern glass pyramid in Memphis containing a Bass Pro Shop. | I10: Comparison | J10: Dark Humor | K10: History/Mythology | L10: Logical | M10: =IF(COUNTIF($A$2:A10, A10)>1, "Dublet", "OK") -> OK
A11: 1be8p2s | B11: Sabrina | C11: Done | D11: It's a football thing Hosted in Brazil, best international team historically and huge favourites to win, they crashed out the tournament to Germany with a 7-1 loss. One of the most shocking results in football. Brazilian fans did not take the loss well. | E11: The humor arises from a reference to the widely recognized “6–7” event, which gives the expression an additional, non-mathematical meaning. | F11: The humor stems from the strong cultural association of the “6–7” reference in Brazil, where repeated exposure to the event evokes an emotional response. | G11: A meme with text at the top reading “Teacher: what is 7-1? Me: 6 My Brazilian classmates:” followed by an image of people wearing yellow shirts reacting emotionally in what appears to be a stadium setting. | H11: A meme with text at the top reading “Teacher: what is 7-1? Me: 6 My Brazilian classmates:” followed by an image of people wearing yellow shirts reacting emotionally in what appears to be a stadium setting. | I11: Incongruity | J11: Situational | K11: Pop culture | L11: General knowledge | M11: =IF(COUNTIF($A$2:A11, A11)>1, "Dublet", "OK") -> OK
A12: 1bikyy1 | B12: Sabrina | C12: Done | D12: The math is a little off, but the gist of it is that the grand canyon took a long *long* time to get to its current state, but, at some point in the very distant past, it would've started out as a small stream, as depicted in the meme. So, the joke is that the Flintstones were around a long time ago when the Grand Canyon was still just a little stream. | E12: The humor arises from an incongruity in scale, where the Grand Canyon is depicted as disproportionately small relative to the characters, implying that people in the past were significantly larger than in reality. This contrast highlights the absurdity of the scene. | F12: The humor stems from an implicit exaggeration of the Grand Canyon’s size, reflecting the tendency to describe it as exceptionally vast in comparison to its representation in the image. | G12: A meme with the text “So that's the Grand Canyon, huh?” followed by “– The Flintstones,” showing a cartoon scene of characters standing near a narrow canyon with a small stream running through it. | H12: A meme with the text “So that's the Grand Canyon, huh?” followed by “– The Flintstones,” showing a cartoon scene of characters standing near a narrow canyon with a small stream running through it. | I12: Sarcasm/Irony | J12: Incongruity | K12: History/Mythology | L12: General knowledge | M12: =IF(COUNTIF($A$2:A12, A12)>1, "Dublet", "OK") -> OK
A13: 1bl3eve | B13: Sabrina | C13: Done | D13: Been a while since I read the books but basically, phones attract monsters for some reason, so Demigods don’t carry them around. | E13: The humor arises from the implausibility of using an iPod as a means of confronting Medusa, highlighting the absurdity of the situation. | F13: The humor stems from the anachronistic coexistence of Medusa and Percy Jackson, combining mythological elements with a modern setting. | G13: A screenshot of a social media post referencing Percy Jackson using an iPod to fight Medusa, accompanied by two images: one of a character holding a device and another showing Medusa’s reflection in the device. Below, a reply comments that it is funny because they did not have phones. | H13: A screenshot of a social media post referencing Percy Jackson using an iPod to fight Medusa, accompanied by two images: one of a character holding a device and another showing Medusa’s reflection in the device. Below, a reply comments that it is funny because they did not have phones. | I13: Incongruity | J13: Sarcasm/Irony | K13: Hobby | L13: Logical | M13: =IF(COUNTIF($A$2:A13, A13)>1, "Dublet", "OK") -> OK
... A165: 1mluk7a | B165: Naomi | C165: Done | D165: After WW2 countless people had to plant trees to restock wood with mostly monoculture forests, as ressource for rebuilding the mostly destroyed country. During the war way more wood was taken off the land then replanted. | E165: Its a joke because of their differing climates amking it an impossible comaprison. | F165: Text over a leafy background discusses Germany being "green" compared to Spain. Below the text, a man in a black sweater touches his nose while looking to the side. | G165: Because the the vastly different land per capita comparison | H165: Text over a leafy background discusses Germany being "green" compared to Spain. Below the text, a man in a black sweater touches his nose while looking to the side. | I165: Dark Humor | J165: Comparison | K165: History/Mythology | L165: politics | M165: =IF(COUNTIF($A$2:A165, A165)>1, "Dublet", "OK") -> OK
A166: 1mpg380 | B166: Naomi | C166: Done | D166: Frustration's attack power depends on how low your friendship is. If Frustration is dealing some big damage, you've got a shitty trainer on your hands Edit: Also it's a Sylveon, which requires the OPPOSITE of what Frustration demands, so yeah that other trainer has done things to harm this poor creature so much they might have to get banned in-universe Edit 2: Sylveon evolves from Affection in Gen 6 and 7, IDK why that got nixed in Gen 8 onwards | E166: This image shows a digital menu for the Pokémon Sylveon with the moves Frustration, Dazzling Gleam, Hyper Beam, and Focus Energy selected. Below the menu is a two-panel meme featuring Mr. Incredible, with a colorful version labeled "THOSE WHO DON'T KNOW" on the left and a dark, distorted version labeled "THOSE WHO KNOW" on the right. | F166: On the surface it seems like a cute pink creature but when you read closer frustration is one of its key traits. | G166: This is a famously difficult game if your loadut is incorrect and this is one of them. | H166: This image shows a digital menu for the Pokémon Sylveon with the moves Frustration, Dazzling Gleam, Hyper Beam, and Focus Energy selected. Below the menu is a two-panel meme featuring Mr. Incredible, with a colorful version labeled "THOSE WHO DON'T KNOW" on the left and a dark, distorted version labeled "THOSE WHO KNOW" on the right. | I166: Situational | K166: Hobby | M166: =IF(COUNTIF($A$2:A166, A166)>1, "Dublet", "OK") -> OK
A167: 1eexgq9 | B167: Naomi | C167: Done | D167: Argentina is where a lot of nazi refugees fled from Germany as the outcome of WW2 was becoming more certain to avoid capture by the allies. As a result, many of their descendants still live there, so you end up with some Argentinians with suspiciously German last names and lineage. | E167: It is a joke because Argntianians have famously "less latiny names" | F167: It is funny bercause German last names are some of the most common throughut the whole world. | G167: The image features the header "Argentinians be like:" above two photos labeled "First Name" and "Last Name." Under "First Name," a man is shown in a traditional matador outfit with a cape, and under "Last Name," a man is wearing a black Nazi SS military uniform with a swastika armband. | H167: The image features the header "Argentinians be like:" above two photos labeled "First Name" and "Last Name." Under "First Name," a man is shown in a traditional matador outfit with a cape, and under "Last Name," a man is wearing a black Nazi SS military uniform with a swastika armband. | I167: Dark Humor | K167: History/Mythology | M167: =IF(COUNTIF($A$2:A167, A167)>1, "Dublet", "OK") -> OK
A168: 1cs870m | B168: Naomi | C168: Done | D168: Nada means nothing but also swim, he asked what's up | E168: It is funny because penguins dont talk. | F168: It is funny because penguins dont speak spanish. | G168: The image contains a social media post with the text, "i'm literally so bored i just realized that 'no' is 'on' backwards." Below the text is a reaction photo of a man with a shocked, wide-eyed expression. | H168: The image contains a social media post with the text, "i'm literally so bored i just realized that 'no' is 'on' backwards." Below the text is a reaction photo of a man with a shocked, wide-eyed expression. | I168: Wordplay | K168: General knowledge | M168: =IF(COUNTIF($A$2:A168, A168)>1, "Dublet", "OK") -> OK
A169: 1g1cv45 | B169: Naomi | C169: Done | D169: He is putting water into the empty bottle, to shake it up and make soapy water, to get an extra wash out of the bottle before throwing it away. | E169: It funny because the animal is sad and it is asumed that one would be happy having fufillled thier childhood goals. | F169: It is funny because animals dont shower themselves ad wouldnt know to put water in the bottle of soap to get an extra use. | G169: He is putting water into the empty bottle, to shake it up and make soapy water, to get an extra wash out of the bottle before throwing it away. | H169: He is putting water into the empty bottle, to shake it up and make soapy water, to get an extra wash out of the bottle before throwing it away. | I169: Comparison | K169: meme | M169: =IF(COUNTIF($A$2:A169, A169)>1, "Dublet", "OK") -> OK
A170: 1g2ofgo | B170: Naomi | C170: Done | D170: Traditional ways of observing Yom Kippur include abstaining from food, washing, and sex, so it's not really normal to wish a happy" Yom Kippur to anyone" | E170: That is not traditionally how you greet someone on yom kippur. | F170: It is funny because on Yom Kippur jews usually dont use phones as technology is forbidden to keep kosher lifestyle. | G170: A 4 panel meme with screenshots from the terminator with him wishing th woman on the phone "Happy Yom Kipur" her returning the greeting and then the man telling the child his parents are dead. | H170: A 4 panel meme with screenshots from the terminator with him wishing th woman on the phone "Happy Yom Kipur" her returning the greeting and then the man telling the child his parents are dead. | I170: Situational | K170: History/Mythology | M170: =IF(COUNTIF($A$2:A170, A170)>1, "Dublet", "OK") -> OK
A171: 1jzu8un | B171: Naomi | C171: Done | D171: What's wrong with McAfee?What's wrong with McAfee? That question is a different topic, anyway the joke is that even if you uninstall it somehow it'll find its way back to your PC or just won't let you do it at all. | E171: A man labeled "Me" physically ejects another man labeled "McAfee" from a building. After the first man turns around to dust off his hands, the second man immediately reappears directly behind him inside the room. | F171: It is a joke refering to the common trope that there is always one friend you cant get rid of. | G171: It isa reference to the character macafee in the Netflix show "the Politician" | H171: A man labeled "Me" physically ejects another man labeled "McAfee" from a building. After the first man turns around to dust off his hands, the second man immediately reappears directly behind him inside the room. | I171: Surprise | K171: Technical | M171: =IF(COUNTIF($A$2:A171, A171)>1, "Dublet", "OK") -> OK
A172: 1gvvhs3 | B172: Naomi | C172: Done | D172: Tea" is slang for gossip" | E172: It is incongruous because a flight attendant would never divuldge this kind of information ti a passenger. | F172: It is funny because the woamn who asked for the tea is the wife. | G172: A flight attendant offers a passenger a choice between coffee or tea, to which the passenger selects tea. The flight attendant then leans in and shares a secret about the captain having a second family while his wife is on the same plane. | H172: A flight attendant offers a passenger a choice between coffee or tea, to which the passenger selects tea. The flight attendant then leans in and shares a secret about the captain having a second family while his wife is on the same plane. | I172: Wordplay | K172: Social conventions | M172: =IF(COUNTIF($A$2:A172, A172)>1, "Dublet", "OK") -> OK
A173: 1l22d3q | B173: Naomi | C173: Done | D173: It’s a pretty significant plot point to do with Yellowjackets, which she is a major character in. let’s just say, to avoid spoilers, wearing the heart necklace in that show is indicative of bad things to follow. also you should watch Yellowjackets | E173: It is a compliment to the woman in the photo saying she is so beautiful she is worth going to war for. | F173: A social media post features two photos of actress Ella Purnell, with a caption comparing her facial expression to a portrait one would carry in a heart locket during wartime. A comment below the photos suggests that she has already seen enough heart necklaces. | G173: The poster assumed that since she is beautiful she has already been gifted lots of jewlery. | H173: A social media post features two photos of actress Ella Purnell, with a caption comparing her facial expression to a portrait one would carry in a heart locket during wartime. A comment below the photos suggests that she has already seen enough heart necklaces. | I173: Sarcasm/Irony | K173: Pop culture | M173: =IF(COUNTIF($A$2:A173, A173)>1, "Dublet", "OK") -> OK
A174: 1j289je | B174: Naomi | C174: Done | D174: Penguins are a brand of individually wrapped biscuits | E174: It is a joke about platic toys and how two animals who would never coexist in nature are able to in plastic form. | F174: Elephants have famously thick and wrinkly skin. | G174: A person holds a small slip of paper featuring a joke about elephants and penguins. The text asks why elephants do not like penguins, followed by the answer: "They can't get the wrappers off." | H174: A person holds a small slip of paper featuring a joke about elephants and penguins. The text asks why elephants do not like penguins, followed by the answer: "They can't get the wrappers off." | I174: Incongruity | K174: General knowledge | M174: =IF(COUNTIF($A$2:A174, A174)>1, "Dublet", "OK") -> OK
A175: 1ga3uxo | B175: Naomi | C175: Done | D175: It prints out the 8th letter of the Sinhala alphabet, which is the official language of Sri Lanka. The alphabet looks like this: ඞ Amogus. | E175: It is a script that deletes your entire computer. | F175: It is a script that installs a virus that sends all your passwords and usernames to hackers. | G175: An image shows Peter Griffin from Family Guy running through a field while being chased by a plane. Overlaying the scene is a line of Python code and a warning to not print it, calling it the "worst mistake of my life." | H175: An image shows Peter Griffin from Family Guy running through a field while being chased by a plane. Overlaying the scene is a line of Python code and a warning to not print it, calling it the "worst mistake of my life." | I175: Surprise | K175: Technical | M175: =IF(COUNTIF($A$2:A175, A175)>1, "Dublet", "OK") -> OK
A176: 1l99mtp | B176: Naomi | C176: Done | D176: The answer is: horse legs don't bend that way. | E176: The busha upon frst glance looks like the head of a person. | F176: There are no such places in Auburn California. | G176: A framed sketch of a white horse is displayed on a wall above a wooden cabinet in a hotel foyer. A small, round topiary plant on the cabinet is positioned directly in front of the bottom of the painting, overlapping the horse's underside. | H176: A framed sketch of a white horse is displayed on a wall above a wooden cabinet in a hotel foyer. A small, round topiary plant on the cabinet is positioned directly in front of the bottom of the painting, overlapping the horse's underside. | I176: Situational | K176: Technical | M176: =IF(COUNTIF($A$2:A176, A176)>1, "Dublet", "OK") -> OK
A177: 1hjwowy | B177: Naomi | C177: Done | D177: It was posted by someone who identifies as GenX. That’s all there is to it. | E177: Gen X is uusally not as mentioned when discussing generational differences. | F177: A four-panel meme characterizes different generations through various emotional reactions: Millennials and Boomers are shown shouting and pointing, while Gen Z is shown crying into a headset. In the final panel, Gen X is depicted looking on calmly while holding a drink. | G177: It shws people depicted by their age. | H177: A four-panel meme characterizes different generations through various emotional reactions: Millennials and Boomers are shown shouting and pointing, while Gen Z is shown crying into a headset. In the final panel, Gen X is depicted looking on calmly while holding a drink. | I177: Exaggeration | K177: Social conventions | M177: =IF(COUNTIF($A$2:A177, A177)>1, "Dublet", "OK") -> OK
... A187: 1it3ezt | B187: Naomi | C187: Done | D187: As for a bee, he refers to an F-22 stealth fighter, whose radar-cross section is comparable to a bee. SO the radar says that there's a bee flying at mach 2 | E187: An image captioned "POV: You're in a Su-57 and a bee is approaching you at mach 2" showing a close-up of a gray and orange calico cat staring directly at the camera with a wide-eyed, worried expression. | F187: It is because the bee would most definetly be killed instantly by the object going mach 2. | G187: Its funny becaue a cat coukd never be a pilot. | H187: An image captioned "POV: You're in a Su-57 and a bee is approaching you at mach 2" showing a close-up of a gray and orange calico cat staring directly at the camera with a wide-eyed, worried expression. | I187: Wordplay | K187: Technical | M187: =IF(COUNTIF($A$2:A187, A187)>1, "Dublet", "OK") -> OK
A188: 1ceuuuh | B188: Sabrina | C188: Done | D188: They're all pregnant. Can't deploy pregnant people | E188: They are wearing longer jackets as a way of respecting Iran’s expectations around modest clothing. It looks like they are trying to adapt to the country’s rules and avoid standing out too much. | F188: The woman looks kind of dull and uninterested, like she is not exactly excited to be there. Her expression makes it seem as if the whole trip or situation is not really her vibe. | G188: At the top, the meme says, “Single female Soldiers when they hear they might deploy to Iran.” Under the text, a pregnant female soldier is shown from three different angles while wearing a military uniform. | H188: At the top, the meme says, “Single female Soldiers when they hear they might deploy to Iran.” Under the text, a pregnant female soldier is shown from three different angles while wearing a military uniform. | I188: Sarcasm/Irony | J188: Situational | K188: politics | L188: Logical | M188: =IF(COUNTIF($A$2:A188, A188)>1, "Dublet", "OK") -> OK
A189: 1bk5jkq | B189: Sabrina | C189: Done | D189: Noone's sure why saturn has a hexagon There's hypotheses, but noone's completely sure that's what the meme is referring to | E189: It is not actually a hexagon, which is basically the whole troll part of the meme. The image acts like it is showing something obvious or scientific, but the shape does not even match what it claims. | F189: Saturn’s hexagon is a real cloud pattern around the planet’s north pole, which is why the reference works. The meme depends on recognizing that Saturn is known for having this strange, almost hexagonal storm-like formation. | G189: This four-panel meme focuses on Saturn’s hexagon-shaped pole. It starts with a simple image of Saturn, then moves into darker and more dramatic edits where different meme faces react to the hexagon. | H189: This four-panel meme focuses on Saturn’s hexagon-shaped pole. It starts with a simple image of Saturn, then moves into darker and more dramatic edits where different meme faces react to the hexagon. | I189: Surprise | J189: Situational | K189: Technical | L189: Hobby | M189: =IF(COUNTIF($A$2:A189, A189)>1, "Dublet", "OK") -> OK
A190: 1az5r39 | B190: Sabrina | C190: Done | D190: Food prices in Canada are very high | E190: In America people have the whole American Dream thing where everyone is told they can work hard and maybe become rich one day. | F190: Bugs Bunny appears in two separate panels with different flags behind him. In the first panel, the American flag is shown with the words “work or starve,” while the second panel uses the Canadian flag and changes the phrase to “work and starve.” | G190: In Canada it feels more like people get a decent amount and the whole society is supposed to be a bit more equal. | H190: Bugs Bunny appears in two separate panels with different flags behind him. In the first panel, the American flag is shown with the words “work or starve,” while the second panel uses the Canadian flag and changes the phrase to “work and starve.” | I190: Comparison | J190: Exaggeration | K190: politics | L190: General knowledge | M190: =IF(COUNTIF($A$2:A190, A190)>1, "Dublet", "OK") -> OK
A191: 1hauo6q | B191: Sabrina | C191: Done | D191: A McDonald's employee collected the prize bag on identifying the UnitedHealth CEO assassin. | E191: A “Marked Safe” style post is shown with a small blue flag icon above the text. The message says that the person is marked safe from being the most hated McDonald’s employee in the country today. | F191: No matter how hated you think you are there is always someone people hate even more lol. | G191: Working at McDonald’s already makes some people judge you because of all the boycotts and politics around it. | H191: A “Marked Safe” style post is shown with a small blue flag icon above the text. The message says that the person is marked safe from being the most hated McDonald’s employee in the country today. | I191: Dark Humor | J191: Exaggeration | K191: politics | L191: Pop culture | M191: =IF(COUNTIF($A$2:A191, A191)>1, "Dublet", "OK") -> OK
A192: 1jtym4e | B192: Sabrina | C192: Done | D192: That scar looks like the one left by the BCG (Bacille Calmette-Guérin) vaccine. It prevents tuberculosis. Many immigrants are seen with this scar. | E192: The meme begins with ICE asking, “are you Mexican,” followed by the reply “No.” Beneath that, the image compares a mark on someone’s skin with a suspicious facial expression labeled as ICE. | F192: ICE is shown as thinking someone is illegal just because they are Mexican which makes the whole thing feel racist and unfair. | G192: ICE does not only go after Mexicans. They target immigrants in general so it is bigger than just one group. | H192: The meme begins with ICE asking, “are you Mexican,” followed by the reply “No.” Beneath that, the image compares a mark on someone’s skin with a suspicious facial expression labeled as ICE. | I192: Dark Humor | J192: Exaggeration | K192: politics | L192: Social conventions | M192: =IF(COUNTIF($A$2:A192, A192)>1, "Dublet", "OK") -> OK
A193: 1l4x3e6 | B193: Sabrina | C193: Done | D193: They are implying a relationship between trumps youngest son, Baron, and elons daughter, Vivian, would end the petty squabbles and reunite the 2 fathers. | E193: If Putin’s daughter and Trump’s son got together, it would basically mean world peace. | F193: A tweet says there is a long-standing way to resolve current political tension and that the user should not have to spell it out. Below the text are two photos placed side by side, one of a young blonde woman and one of a young man in a suit. | G193: Trump’s son having a model girlfriend would make him happier and probably less awkward overall. | H193: A tweet says there is a long-standing way to resolve current political tension and that the user should not have to spell it out. Below the text are two photos placed side by side, one of a young blonde woman and one of a young man in a suit. | I193: Surprise | J193: Exaggeration | K193: politics | L193: Logical | M193: =IF(COUNTIF($A$2:A193, A193)>1, "Dublet", "OK") -> OK
A194: 1mahcad | B194: Sabrina | C194: Done | D194: penguin also happens to be the name of a chocolate bar p-p-pick up a penguin | E194: Penguins are tough animals, so eating one would obviously not be easy. | F194: Getting the wrapper off a Penguin bar is already hard for humans, so an elephant would have no chance. | G194: A small paper joke card is lying on a wooden table. The card asks, “Why don’t elephants like penguins?” and answers, “They can’t get the wrappers off.” | H194: A small paper joke card is lying on a wooden table. The card asks, “Why don’t elephants like penguins?” and answers, “They can’t get the wrappers off.” | I194: Wordplay | J194: Situational | K194: General knowledge | L194: meme | M194: =IF(COUNTIF($A$2:A194, A194)>1, "Dublet", "OK") -> OK
A195: 1j0n4gg | B195: Sabrina | C195: Done | D195: Loss of US support for zelenski and Ukraine means Russia and its allies will have a considerable advantage, this image depicts them revelling in this information. | E195: Men love gossip just as much as women do, they just pretend they do not. | F195: A four-panel phone-call meme shows three political leaders holding phones. The captions suggest that one leader asks if another is seeing something, then a third joins the call with a loud phone sound. | G195: When the tea is good enough, even men are calling their homeboys immediately. | H195: A four-panel phone-call meme shows three political leaders holding phones. The captions suggest that one leader asks if another is seeing something, then a third joins the call with a loud phone sound. | I195: Surprise | J195: Sarcasm/Irony | K195: politics | L195: meme | M195: =IF(COUNTIF($A$2:A195, A195)>1, "Dublet", "OK") -> OK
A196: 1hbogj4 | B196: Sabrina | C196: Done | D196: The United Health Care CEO shooter was recently apprehended in Pennsylvania in a McDonald’s after a tip was called in by another customer, contrary to the current belief that it was an employee. The meme is implying that the McDonald’s worker would also snitch on Anne Frank, who was hiding in an attic from the Nazis, because of the belief a McDonald’s employee snitched | E196: Comparing Anne Frank hiding from the Nazis to someone being murdered by a civilian from a major company makes no sense. Those two situations are nowhere near the same level. | F196: Anne Frank’s hiding place has become such a tourist spot now that there is even a McDonald’s nearby where people can ask for directions. | G196: A fast-food worker is shown smiling while holding a kitchen utensil. The text above her says, “Anne Frank? Yeah, she’s in the attic.” | H196: A fast-food worker is shown smiling while holding a kitchen utensil. The text above her says, “Anne Frank? Yeah, she’s in the attic.” | I196: Dark Humor | J196: Sarcasm/Irony | K196: politics | L196: Pop culture | M196: =IF(COUNTIF($A$2:A196, A196)>1, "Dublet", "OK") -> OK
A197: 1flb4nk | B197: Sabrina | C197: Done | D197: The show being referenced is the mockumentary Cunk on Earth, where the titular narrator humorously misinterprets history. The Romans left a lot from their history, including pottery fragments (which broke due to the long time period), which Cunk humorously says is caused by their clumsiness. | E197: A social media post shows a woman standing in front of ancient ruins. Below it, another post says that based on the amount of pottery fragments, the Roman Empire may have been the clumsiest empire in history. | F197: Materials have changed a lot since ancient times, so pottery today can last much longer than pottery from the Roman Empire. | G197: Someone probably broke the pottery on purpose just to mess with the Roman Empire. | H197: A social media post shows a woman standing in front of ancient ruins. Below it, another post says that based on the amount of pottery fragments, the Roman Empire may have been the clumsiest empire in history. | I197: Surprise | J197: Sarcasm/Irony | K197: History/Mythology | L197: Logical | M197: =IF(COUNTIF($A$2:A227, A197)>1, "Dublet", "OK") -> OK
A198: 1dhf9h2 | B198: Sabrina | C198: Done | D198: Donald Trump saying electric boats are heavy and will sink. You either get electrocuted by the battery or face a shark. | E198: There are not sharks everywhere in the ocean, so acting like the only options are “safe water” or “shark attack” is way too dramatic. | F198: A meme shows two politicians sitting on a couch, with one laughing while the other bends forward. Text above them says, “So there’s a boat, A battery and a shark 10 yards away.” | G198: It shows Hillary and Obama secretly plotting together to get rid of Trump. | H198: A meme shows two politicians sitting on a couch, with one laughing while the other bends forward. Text above them says, “So there’s a boat, A battery and a shark 10 yards away.” | I198: Surprise | J198: Comparison | K198: politics | L198: Social conventions | M198: =IF(COUNTIF($A$2:A198, A198)>1, "Dublet", "OK") -> OK
A199: 1c01lei | B199: Sabrina | C199: Done | D199: A British prime minister who the IRA tried to blow up. | E199: It looks like they are planning to bomb the non-binary person, which makes the situation feel way darker and more absurd than expected. | F199: Even when people travel back in time to warn them that the bomb will not kill Thatcher, they still do not seem to take it seriously. They are so focused on the plan that the warning barely matters to them. | G199: A time-machine meme compares girls, boys, and a non-binary person using a time machine. Each section shows a character giving advice to a group of masked men, with the group responding that they will do better. | H199: A time-machine meme compares girls, boys, and a non-binary person using a time machine. Each section shows a character giving advice to a group of masked men, with the group responding that they will do better. | I199: Dark Humor | J199: Exaggeration | K199: politics | L199: Logical | M199: =IF(COUNTIF($A$2:A199, A199)>1, "Dublet", "OK") -> OK
A200: 1d7u657 | B200: Sabrina | C200: Done | D200: To Kill a Mockingbird Story: In 1932 Alabama, a widowed lawyer with two small children defends a black man accused of raping a white woman. | E200: The image combines a social media post about believing rape victims with a black-and-white courtroom scene from an old film. Two men are seated in court while people watch from the background. | F200: The situation is wild because the widowed lawyer is still helping the man accused of rape, even though that same man is also connected to the death of his wife. It makes the scene feel morally twisted, since he is defending someone who has caused him personal harm. | G200: The point is that people often treat male victims with way more doubt, especially in cases involving sexual assault. The reaction becomes uncomfortable because it suggests that being taken seriously depends on gender rather than the actual situation. | H200: The image combines a social media post about believing rape victims with a black-and-white courtroom scene from an old film. Two men are seated in court while people watch from the background. | I200: Sarcasm/Irony | J200: Comparison | K200: politics | L200: Hobby | M200: =IF(COUNTIF($A$2:A200, A200)>1, "Dublet", "OK") -> OK
...

Sheet Lists
A1: Assigned | B1: Status | D1: Humor (Primary) | E1: Count Humor | F1: Mangler | G1: Mål | I1: Context (Primary) | J1: Count context | K1: Mangler | L1: Mål | N1: farvekode | O1: Antal billeder for style | P1: Antal billeder for context | R1: Picture annotations | S1: Name | T1: status | U1: Progress | V1: Mål
A2: Sabrina | B2: Not started | D2: Wordplay | E2: =COUNTIFS(Annotations!I:I,D2,Annotations!C:C,"Done") -> 62 | F2: =MAX(0,$G2-E2) -> 1 | G2: 63 | I2: Pop culture | J2: =COUNTIFS(Annotations!K:K,I2,Annotations!C:C,"Done") -> 64 | K2: =MAX(0,$L2-J2) -> 0 | L2: 56 | N2: 0-30% | O2: 0-21 | P2: 0-16 | S2: Sabrina | T2: Done | U2: =COUNTIFS(Annotations!B:B,A2,Annotations!C:C,"Done") -> 251 | V2: 250
A3: Naomi | B3: In progress | D3: Situational | E3: =COUNTIFS(Annotations!I:I,D3,Annotations!C:C,"Done") -> 63 | F3: =MAX(0,$G3-E3) -> 0 | G3: 63 | I3: meme | J3: =COUNTIFS(Annotations!K:K,I3,Annotations!C:C,"Done") -> 42 | K3: =MAX(0,$L3-J3) -> 14 | L3: 56 | N3: 31-74% | O3: 22-53 | P3: 17-40 | S3: Naomi | T3: Done | U3: =COUNTIFS(Annotations!B:B,A3,Annotations!C:C,"Done") -> 251 | V3: 250
B4: Done | D4: Comparison | E4: =COUNTIFS(Annotations!I:I,D4,Annotations!C:C,"Done") -> 65 | F4: =MAX(0,$G4-E4) -> 0 | G4: 63 | I4: Social conventions | J4: =COUNTIFS(Annotations!K:K,I4,Annotations!C:C,"Done") -> 65 | K4: =MAX(0,$L4-J4) -> 0 | L4: 56 | N4: 75%-100% | O4: 54-72 | P4: 41-56
D5: Exaggeration | E5: =COUNTIFS(Annotations!I:I,D5,Annotations!C:C,"Done") -> 63 | F5: =MAX(0,$G5-E5) -> 0 | G5: 63 | I5: Technical | J5: =COUNTIFS(Annotations!K:K,I5,Annotations!C:C,"Done") -> 57 | K5: =MAX(0,$L5-J5) -> 0 | L5: 56 | R5: Partner Annotations | S5: Name | T5: status | U5: Progress | V5: Mål
D6: Sarcasm/Irony | E6: =COUNTIFS(Annotations!I:I,D6,Annotations!C:C,"Done") -> 64 | F6: =MAX(0,$G6-E6) -> 0 | G6: 63 | I6: Hobby | J6: =COUNTIFS(Annotations!K:K,I6,Annotations!C:C,"Done") -> 58 | K6: =MAX(0,$L6-J6) -> 0 | L6: 56 | S6: Sabrina | T6: Done | U6: =COUNTIFS(PAnnotations!J:J,A2,PAnnotations!K:K,"Done") -> 0 | V6: 25
D7: Surprise | E7: =COUNTIFS(Annotations!I:I,D7,Annotations!C:C,"Done") -> 55 | F7: =MAX(0,$G7-E7) -> 8 | G7: 63 | I7: Logical | J7: =COUNTIFS(Annotations!K:K,I7,Annotations!C:C,"Done") -> 50 | K7: =MAX(0,$L7-J7) -> 6 | L7: 56 | S7: Naomi | T7: Done | U7: =COUNTIFS(PAnnotations!J:J,A3,PAnnotations!K:K,"Done") -> 25 | V7: 25
D8: Incongruity | E8: =COUNTIFS(Annotations!I:I,D8,Annotations!C:C,"Done") -> 59 | F8: =MAX(0,$G8-E8) -> 4 | G8: 63 | I8: General knowledge | J8: =COUNTIFS(Annotations!K:K,I8,Annotations!C:C,"Done") -> 55 | K8: =MAX(0,$L8-J8) -> 1 | L8: 56
D9: Dark Humor | E9: =COUNTIFS(Annotations!I:I,D9,Annotations!C:C,"Done") -> 71 | F9: =MAX(0,$G9-E9) -> 0 | G9: 63 | I9: politics | J9: =COUNTIFS(Annotations!K:K,I9,Annotations!C:C,"Done") -> 56 | K9: =MAX(0,$L9-J9) -> 0 | L9: 56 | R9: Secondary tags | S9: Name | T9: status | U9: Progress | V9: Mål
I10: History/Mythology | J10: =COUNTIFS(Annotations!K:K,I10,Annotations!C:C,"Done") -> 55 | K10: =MAX(0,$L10-J10) -> 1 | L10: 56 | S10: Sabrina | T10: Done | U10: =COUNTIFS(Annotations!$B$2:$B$505,"Sabrina",Annotations!$J$2:$J$505,"<>",Annotations!$L$2:$L$505,"<>") -> 251 | V10: 250
D11: I alt | E11: =SUM(E2:E9) -> 502 | F11: =500-E11 -> -2 | G11: =SUM(G2:G9) -> 504 | I11: I alt | J11: =SUM(J2:J10) -> 502 | K11: =500-J11 -> -2 | L11: =SUM(L2:L10) -> 504 | S11: Naomi | T11: Done | U11: =COUNTIFS(Annotations!$B$2:$B$505,"Naomi",Annotations!$J$2:$J$505,"<>",Annotations!$L$2:$L$505,"<>") -> 41 | V11: 250
C14: Fokusområde: | H14: Fokusområde:
C15: Wordplay, Sarcasm and Dark humor | H15: meme, politics, historie og hobby

Sheet Notes
A1: AI to use: look for performace gap i disse modeller | B1: Duplicates: slettet fra vores annotation ark | C1: inden vi analysere med AI | D1: Lektie til næste gang | E1: Spørgsmål
A2: GPT5 | B2: 1jfy6ms | C2: Når vi har ramt 500 billeder skal vi sørge for alt teksten er ensartet, dvs. enten punktum på alle eller ingen, fjerne indrykning, fjerne citationstegn, stort bogstav for alle sætninger etc. | D2: Find akademiske kilder 3-4 hver, kilderne skal være nuanceret (artikler, bøger m.m.) | E2: skal vi lave en komparativ analyse? Dvs. Skal vi sammenligne Fridas resultater med vores? Fx om vi kan sige om accuracy m.m.
A3: Claude 4.6 | B3: 1gz2i0o | C3: når man omdanner cvs til excel bliver nogle tegn underlige, det skal rettes | D3: Lav en kode som gør teksten ren i annotations
A4: Gemini 3 | B4: 1d6ho4f | C4: vi skal randomisere rækkefølgen af svarmulighederne | D4: En kode der randomisere svarene
A5: Open weight models | B5: 1gqh1c5 | C5: for literal: hvis det er none of the above så lav en ny og ellers så tag den der tættest på | D5: Have en klar outline
A6: Gemma 4 | B6: 1mfr9vy | D6: Skrive analyse delen
A7: Qwen3.5 | B7: 1j983b2
C8: Lav en sekundær tag til billederne | D8: Naomi: finish csv file and adjust frida code to run experiment
D9: Outline: Naomi (2 related work) Sabrina (3 data)
D10: Lav 25 partner annotations til hinandens random
D11: Skriv til desmond
D12: Sabrina: Lav secondary tags til billederne
D13: Sabrina: Lav progress for partner annotation

Sheet Definitions
A1: Context definitions | B1: How to use them correctly | C1: Examples | D1: Humor style definitions | E1: How to use them correctly | F1: Examples
A2: popculture | B2: Requires knowledge of widely known media, celebrities, movies, music, or mainstream entertainment. | C2: This is me waiting like Harry Potter for my letter
A3: Meme | B3: Requires familiarity with a specific internet meme format or template. | C3: “This is fine.” (dog sitting in a burning room)
A4: Social conventions | B4: Requires understanding of social norms, roles, or expected behavior between people. | C4: Saying ‘you too’ to the waiter when they say enjoy your meal.
A5: Technical | B5: Requires specialized or domain-specific knowledge (e.g. programming, science, psychology). | C5: Fixing a bug by commenting out the code.
A6: Hobby | B6: Requires insider knowledge of a niche interest or community (e.g. Warhammer, fishing). | C6: Only Warhammer players know this pain…
A7: Logical | B7: Requires understanding of reasoning, logic, or a flawed/absurd conclusion. | C7: If tomatoes are fruit, then ketchup is a smoothie.
A8: General knowledge | B8: Requires broad, common knowledge about the world that most people are expected to know. | C8: Nokia phones never break
A9: Politics | B9: Requires knowledge of political systems, conflicts, ideologies, or current affairs. | C9: Russia taking land like my neighbor taking my parking spot.
A10: History/Mythology | B10: Requires knowledge of historical events, figures, or mythological stories. | C10: Medusa turning men to stone
A13: sarcasm/Irony
A14: Wordplay/rhymes
A15: Social/Cultural Norms.

Sheet PAnnotations
A1: File | B1: Assigned_to | C1: Status | D1: Correct answer | E1: Literal_Description | F1: Humor Style | G1: Humor style secondary | H1: Contextual Knowledge | I1: Contextual Knowledge secondary | J1: Partner name | K1: Status | L1: Partner: Humor Style | M1: Partner: Humor style secondary | N1: Partner: Contextual Knowledge | O1: Partner: Contextual Knowledge secondary | P1: Duplicate check
A2: 1actpx8 | B2: Sabrina | C2: Done | D2: the meme refers to cloudy and a chance of meatballs (movie): the main character is a scientist and sprayed on shoes when he was a kid, which he could never remove | E2: a snapchat picture showing a person holding a can of Flex Seal and their foot covered in a black substance, with the text ‘Flex seal shoe’ with the text underneath: "did the tales of falling meatballs not weigh on thine conscious". | F2: Sarcasm/Irony | H2: Hobby | J2: Naomi | K2: Done | L2: Sarcasm/Irony | M2: Situational | N2: Hobby | O2: Pop culture | P2: =IF(COUNTIF($A$2:A2, A2)>1, "Dublet", "OK") -> OK
A3: 1af8odu | B3: Sabrina | C3: Done | D3: A teller is a person who works at the front desk of a bank. Teller is also a person's name; that person is one half of the magician duo Penn & Teller. On stage, Teller doesn't speak. Penn is the one who explains everything/talks to the crowd. The joke is that you expect the robber to be speaking to a bank teller. But he's actually speaking to the magician Teller who doesn't talk. That's why Penn comes in at the end to explain what's going on. | E3: A tweet-style image shows a fictional dialogue where a bank robber repeatedly asks a teller where the safe is. The teller gives no visible response, and the robber becomes confused. The final line says, “PENN: He always does this,” implying the teller is the magician Teller, who is known for staying silent. | F3: Wordplay | H3: Pop culture | J3: Naomi | P3: =IF(COUNTIF($A$2:A3, A3)>1, "Dublet", "OK") -> OK
A4: 1ajzxfm | B4: Sabrina | C4: Done | D4: It’s kind of a weird joke that doesn’t make perfect sense, but here’s the intended meaning: 1. Many people might see something like 50/50 odds leading to 20 successes in a row and think the next one is more likely to be a failed surgery. Like how many people could flip a coin and get heads twice in a row, and be more likely to guess the next coinflip would be tails. Hence the nervous face. 2. A statistician would know that the success rate of each surgery is independent of all the other ones, so they wouldn’t be especially nervous theirs would go wrong. 3. A scientist might see 20 successes in a row for a surgery with a 50% survival rate and think “wow, this doctor must be really good at doing surgeries” | E4: A meme with text describing a doctor stating that a surgery has a 50% survival rate and that the last 20 patients survived. Below the text are three panels labeled ‘Normal people’, ‘Mathematician’, and ‘Scientist’, each showing a different face reacting to the statement. | F4: Comparison | H4: Logical | J4: Naomi | P4: =IF(COUNTIF($A$2:A4, A4)>1, "Dublet", "OK") -> OK
A5: 1amtoff | B5: Sabrina | C5: Done | D5: Amazon does not hire 12 year olds, and 12 year olds cannot drive. The potential panic this may cause whomever at Amazon, is hilarious. | E5: A screenshot of a social media thread where a user says that Amazon hired their 12-year-old son, followed by a response from an Amazon customer service account asking for clarification, and a subsequent reply stating that the son is one of their drivers | F5: Incongruity | H5: General knowledge | J5: Naomi | K5: Done | L5: Incongruity | M5: Sarcasm/Irony | N5: General knowledge | O5: politics | P5: =IF(COUNTIF($A$2:A5, A5)>1, "Dublet", "OK") -> OK
A6: 1aoxsw3 | B6: Sabrina | C6: Done | D6: Deer run in circles as a defense mechanism against predators ants run in circles because an ant has to turn around & left a pheromone trail in a circle, so the ants will die. it’s very sad. | E6: “A meme with the caption ‘Animals running in circles is so cool’ at the top, followed by two images of animals arranged in circular formations. Below the images are two panels with illustrated faces, labeled ‘Deers’ on the left and ‘Ants’ on the right, each showing a different facial expression.” | F6: Situational | H6: Technical | J6: Naomi | P6: =IF(COUNTIF($A$2:A6, A6)>1, "Dublet", "OK") -> OK
A7: 1asrnb3 | B7: Sabrina | C7: Done | D7: The black car is the Impala (aka “Metallicar”/“Baby”) from *Supernatural*, a show about two brothers who hunt down paranormal phenomena like ghosts, demons, etc. The Mystery Machine, of course, is Scooby Doo and the Scooby Gang, who hunt down ghosts and other various monsters. If they’re both in the same place, some haunted stuff is going down. | E7: A meme with the text “oh this place is HAUNTED haunted” at the top, showing a black car parked in front of a colorful van resembling the Scooby-Doo “Mystery Machine” in a parking lot. | F7: Incongruity | H7: Pop culture | J7: Naomi | P7: =IF(COUNTIF($A$2:A7, A7)>1, "Dublet", "OK") -> OK
A8: 1aya611 | B8: Sabrina | C8: Done | D8: Alabama ruled that frozen embryos count as live children, so this couple is claiming their 3 live children and 5 frozen embryos as 8 total children for tax purposes | E8: A meme showing a couple sitting in an office labeled “Tax Services,” speaking to a man behind a desk. One person says “We’re claiming 8 kids…” and the other adds “3 at home and 5 in the lab.” | F8: Sarcasm/Irony | H8: Social conventions | J8: Naomi | P8: =IF(COUNTIF($A$2:A8, A8)>1, "Dublet", "OK") -> OK
A9: 1b03bqv | B9: Sabrina | C9: Done | D9: we's making up states to mess em up badly | E9: A map of the United States showing state borders, with one state highlighted in yellow and a caption asking viewers to identify it. | F9: Incongruity | H9: politics | J9: Naomi | P9: =IF(COUNTIF($A$2:A9, A9)>1, "Dublet", "OK") -> OK
A10: 1b7unh0 | B10: Sabrina | C10: Done | D10: He would probably also be confused why they had built a second Memphis | E10: A meme divided into two sections labeled “Women with a time machine” and “Men with a time machine.” The top shows a woman pointing a gun at Henry Ford. The bottom shows a man speaking to an ancient Egyptian figure in front of a pyramid, with text about a modern glass pyramid in Memphis containing a Bass Pro Shop. | F10: Comparison | H10: Logical | J10: Naomi | K10: Done | L10: Comparison | M10: Exaggeration | N10: Logical | O10: History/Mythology | P10: =IF(COUNTIF($A$2:A10, A10)>1, "Dublet", "OK") -> OK
A11: 1be8p2s | B11: Sabrina | C11: Done | D11: It's a football thing Hosted in Brazil, best international team historically and huge favourites to win, they crashed out the tournament to Germany with a 7-1 loss. One of the most shocking results in football. Brazilian fans did not take the loss well. | E11: A meme with text at the top reading “Teacher: what is 7-1? Me: 6 My Brazilian classmates:” followed by an image of people wearing yellow shirts reacting emotionally in what appears to be a stadium setting. | F11: Incongruity | H11: Pop culture | J11: Naomi | P11: =IF(COUNTIF($A$2:A11, A11)>1, "Dublet", "OK") -> OK
A12: 1bikyy1 | B12: Sabrina | C12: Done | D12: The math is a little off, but the gist of it is that the grand canyon took a long *long* time to get to its current state, but, at some point in the very distant past, it would've started out as a small stream, as depicted in the meme. So, the joke is that the Flintstones were around a long time ago when the Grand Canyon was still just a little stream. | E12: A meme with the text “So that's the Grand Canyon, huh?” followed by “– The Flintstones,” showing a cartoon scene of characters standing near a narrow canyon with a small stream running through it. | F12: Incongruity | H12: Hobby | J12: Naomi | K12: Done | L12: Incongruity | M12: Surprise | N12: Hobby | O12: Technical | P12: =IF(COUNTIF($A$2:A12, A12)>1, "Dublet", "OK") -> OK
A13: 1bl3eve | B13: Sabrina | C13: Done | D13: Been a while since I read the books but basically, phones attract monsters for some reason, so Demigods don’t carry them around. | E13: A screenshot of a social media post referencing Percy Jackson using an iPod to fight Medusa, accompanied by two images: one of a character holding a device and another showing Medusa’s reflection in the device. Below, a reply comments that it is funny because they did not have phones. | F13: Incongruity | H13: Hobby | J13: Naomi | P13: =IF(COUNTIF($A$2:A13, A13)>1, "Dublet", "OK") -> OK
A14: 1bmtc5u | B14: Sabrina | C14: Done | D14: He likes big butts and he cannot lie. | E14: A black-and-white cartoon of a courtroom scene where a judge asks a witness to swear to tell the truth. The witness, a woman standing at the stand, responds that it will not be necessary. Several people are seated in the courtroom observing the exchange. | F14: Incongruity | H14: Social conventions | J14: Naomi | K14: Done | L14: Situational | M14: Incongruity | N14: Pop culture | O14: Social conventions | P14: =IF(COUNTIF($A$2:A14, A14)>1, "Dublet", "OK") -> OK
A15: 1bsdc0l | B15: Sabrina | C15: Done | D15: The Romans did not like the Germanic Tribes at all. It was in fact the Germanic Tribes that were an important factor in the downfall of the empire Edit: What I have just said is basically a CliffNotes explanation of what really happened. Was obviously more complicated than this but this is the gist of it | E15: A meme titled “Bringing Romans forward in time,” divided into two sections labeled “Expectation” and “Reality.” The top section shows a Roman figure reacting to a modern helicopter alongside a modern character making a dismissive comment. The bottom section shows a Roman figure speaking, with text referencing Germans. | F15: Comparison | H15: History/Mythology | J15: Naomi | P15: =IF(COUNTIF($A$2:A15, A15)>1, "Dublet", "OK") -> OK
A16: 1bw9tb7 | B16: Sabrina | C16: Done | D16: Labs test lipsticks and other cosmetics on mice before opening them to the human market. The process probably involves autopsying the mice to see if any toxic chemicals from the product have entered the liver. | E16: A four-panel comic showing mice in a cage. In the first panels the mice ask where they are being taken and speculate that they are going to a laboratory to test lipstick, expressing excitement. In the final panel, a person in a lab coat is shown carrying the cage in a laboratory setting. | F16: Comparison | H16: General knowledge | J16: Naomi | P16: =IF(COUNTIF($A$2:A16, A16)>1, "Dublet", "OK") -> OK
